
2020-07-27 18:33:05,016 - WARNING: Not Found: /favicon.ico
2020-07-27 18:34:46,151 - WARNING: Not Found: /favicon.ico
2020-07-27 18:35:26,075 - WARNING: Not Found: /favicon.ico
2020-07-27 18:36:15,398 - WARNING: Not Found: /favicon.ico
2020-07-27 18:36:41,982 - WARNING: Not Found: /favicon.ico
2020-07-27 18:38:46,274 - WARNING: Not Found: /favicon.ico
2020-07-27 18:39:51,246 - WARNING: Not Found: /favicon.ico
2020-07-27 18:43:00,087 - WARNING: Not Found: /favicon.ico
2020-07-27 18:44:08,212 - WARNING: Not Found: /favicon.ico
2020-07-27 18:45:34,775 - WARNING: Not Found: /robots.txt
2020-07-27 18:45:37,347 - WARNING: Not Found: /favicon.ico
2020-07-27 18:47:04,491 - WARNING: Not Found: /api/
2020-07-27 18:47:24,458 - WARNING: Not Found: /humans.txt
2020-07-27 18:47:24,461 - WARNING: Not Found: /.well-known/security.txt
2020-07-27 18:47:25,306 - WARNING: Not Found: /favicon.ico
2020-07-27 18:47:26,971 - WARNING: Not Found: /humans.txt
2020-07-27 18:47:27,008 - WARNING: Not Found: /.well-known/security.txt
2020-07-27 18:48:01,291 - WARNING: Not Found: /favicon.ico
2020-07-27 18:50:59,983 - WARNING: Not Found: /favicon.ico
2020-07-27 18:51:00,485 - WARNING: Not Found: /favicon.ico
2020-07-27 18:51:32,525 - WARNING: Not Found: /favicon.ico
2020-07-27 18:55:50,491 - WARNING: Not Found: /favicon.ico
2020-07-27 18:56:09,087 - WARNING: Not Found: /favicon.ico
2020-07-27 18:56:12,240 - WARNING: Not Found: /submitReport
2020-07-27 18:56:14,273 - WARNING: Not Found: /favicon.ico
2020-07-27 19:05:53,646 - WARNING: Not Found: /favicon.ico
2020-07-27 19:15:27,223 - WARNING: Not Found: /favicon.ico
2020-07-27 19:25:23,714 - WARNING: Not Found: /favicon.ico
2020-07-27 19:36:43,210 - WARNING: Not Found: /favicon.ico
2020-07-27 23:26:14,936 - WARNING: Not Found: /favicon.ico
2020-07-27 23:57:51,025 - WARNING: Not Found: /favicon.ico
2020-07-28 00:05:38,749 - WARNING: Not Found: /favicon.ico
2020-07-28 09:14:27,568 - WARNING: Not Found: /favicon.ico
2020-07-28 12:35:41,617 - WARNING: Not Found: /favicon.ico
2020-07-28 13:54:51,567 - WARNING: Not Found: /api/
2020-07-28 14:17:47,877 - WARNING: Not Found: /favicon.ico
2020-07-28 15:40:36,386 - WARNING: Not Found: /favicon.ico
2020-07-28 16:33:33,798 - WARNING: Not Found: /favicon.ico
2020-07-28 16:52:22,572 - WARNING: Not Found: /favicon.ico
2020-07-28 16:54:19,485 - WARNING: Not Found: /api/login/
2020-07-28 16:54:46,258 - WARNING: Not Found: /api/login/
2020-07-28 16:55:04,465 - WARNING: Not Found: /api/upload/attack/log/
2020-07-28 16:55:23,509 - WARNING: Not Found: /user
2020-07-28 16:55:26,297 - WARNING: Not Found: /user/
2020-07-28 16:55:50,892 - WARNING: Forbidden (Referer checking failed - https://denon.connectivity.tw/admin/login/?next=/admin/ does not match any trusted origins.): /admin/login/
2020-07-28 16:56:03,615 - WARNING: Forbidden (Referer checking failed - https://denon.connectivity.tw/admin/login/?next=/admin/ does not match any trusted origins.): /admin/login/
2020-07-28 16:56:08,462 - WARNING: Forbidden (Referer checking failed - https://denon.connectivity.tw/admin/login/?next=/admin/ does not match any trusted origins.): /admin/login/
2020-07-28 16:56:28,252 - WARNING: Forbidden (Referer checking failed - https://denon.connectivity.tw/admin/login/ does not match any trusted origins.): /admin/login/
2020-07-28 16:56:41,794 - WARNING: Forbidden (Referer checking failed - https://denon.connectivity.tw/admin/login/ does not match any trusted origins.): /admin/login/
2020-07-28 16:56:58,843 - WARNING: Forbidden (Referer checking failed - https://denon.connectivity.tw/admin/login/ does not match any trusted origins.): /admin/login/
2020-07-28 16:57:05,096 - WARNING: Forbidden (Referer checking failed - https://denon.connectivity.tw/admin/login/ does not match any trusted origins.): /admin/login/
2020-07-28 16:57:11,698 - WARNING: Forbidden (Referer checking failed - https://denon.connectivity.tw/admin/login/ does not match any trusted origins.): /admin/login/
2020-07-28 16:59:06,616 - WARNING: Forbidden (Referer checking failed - https://denon.connectivity.tw/admin/login/ does not match any trusted origins.): /admin/login/
2020-07-28 16:59:10,345 - WARNING: Forbidden (Referer checking failed - https://denon.connectivity.tw/admin/login/ does not match any trusted origins.): /admin/login/
2020-07-28 16:59:25,845 - WARNING: Forbidden (Referer checking failed - https://denon.connectivity.tw/admin/ does not match any trusted origins.): /admin/login/
2020-07-28 17:00:09,273 - WARNING: Forbidden (Referer checking failed - https://denon.connectivity.tw/ does not match any trusted origins.): /admin/login/
2020-07-28 17:00:17,154 - WARNING: Forbidden (Referer checking failed - no Referer.): /admin/login/
2020-07-28 17:00:32,388 - WARNING: Forbidden (Referer checking failed - https://denon.connectivity.tw/user/login/ does not match any trusted origins.): /admin/login/
2020-07-28 17:01:36,044 - WARNING: Not Found: /admin/a
2020-07-28 17:01:43,033 - WARNING: Forbidden (Referer checking failed - https://denon.connectivity.tw/admin/login/?next=/admin/password_change/ does not match any trusted origins.): /admin/login/
2020-07-28 17:01:51,133 - WARNING: Forbidden (Referer checking failed - https://denon.connectivity.tw/admin/login/?next=/admin/auth/group/ does not match any trusted origins.): /admin/login/
2020-07-28 17:03:42,838 - WARNING: Not Found: /mysite.settings
2020-07-28 17:03:47,967 - WARNING: Not Found: /mysite
2020-07-28 17:04:30,498 - WARNING: Not Found: /favicon.ico
2020-07-28 17:05:45,112 - WARNING: Not Found: /favicon.ico
2020-07-28 17:10:45,700 - WARNING: Not Found: /favicon.ico
2020-07-28 17:11:32,885 - WARNING: Not Found: /favicon.ico
2020-07-28 17:28:47,375 - WARNING: Not Found: /favicon.ico
2020-07-28 17:54:39,617 - WARNING: Not Found: /favicon.ico
2020-07-28 21:08:08,709 - ERROR: Internal Server Error: /api/upload/tcn/rx
Traceback (most recent call last):
  File "/home/ubuntu/.local/lib/python3.6/site-packages/django/core/handlers/exception.py", line 34, in inner
    response = get_response(request)
  File "/home/ubuntu/.local/lib/python3.6/site-packages/django/core/handlers/base.py", line 115, in _get_response
    response = self.process_exception_by_middleware(e, request)
  File "/home/ubuntu/.local/lib/python3.6/site-packages/django/core/handlers/base.py", line 113, in _get_response
    response = wrapped_callback(request, *callback_args, **callback_kwargs)
  File "/home/ubuntu/.local/lib/python3.6/site-packages/django/views/decorators/csrf.py", line 54, in wrapped_view
    return view_func(*args, **kwargs)
  File "./users/views.py", line 98, in upload_tcn_rx
    user = User.objects.get(uuid=uuid)
  File "/home/ubuntu/.local/lib/python3.6/site-packages/django/db/models/manager.py", line 82, in manager_method
    return getattr(self.get_queryset(), name)(*args, **kwargs)
  File "/home/ubuntu/.local/lib/python3.6/site-packages/django/db/models/query.py", line 417, in get
    self.model._meta.object_name
users.models.User.DoesNotExist: User matching query does not exist.
2020-07-28 21:08:12,558 - ERROR: Internal Server Error: /api/upload/tcn/tx
Traceback (most recent call last):
  File "/home/ubuntu/.local/lib/python3.6/site-packages/django/core/handlers/exception.py", line 34, in inner
    response = get_response(request)
  File "/home/ubuntu/.local/lib/python3.6/site-packages/django/core/handlers/base.py", line 115, in _get_response
    response = self.process_exception_by_middleware(e, request)
  File "/home/ubuntu/.local/lib/python3.6/site-packages/django/core/handlers/base.py", line 113, in _get_response
    response = wrapped_callback(request, *callback_args, **callback_kwargs)
  File "/home/ubuntu/.local/lib/python3.6/site-packages/django/views/decorators/csrf.py", line 54, in wrapped_view
    return view_func(*args, **kwargs)
  File "./users/views.py", line 153, in upload_tcn_tx
    user = User.objects.get(uuid=uuid)
  File "/home/ubuntu/.local/lib/python3.6/site-packages/django/db/models/manager.py", line 82, in manager_method
    return getattr(self.get_queryset(), name)(*args, **kwargs)
  File "/home/ubuntu/.local/lib/python3.6/site-packages/django/db/models/query.py", line 417, in get
    self.model._meta.object_name
users.models.User.DoesNotExist: User matching query does not exist.
2020-07-28 21:09:19,311 - ERROR: Internal Server Error: /api/upload/tcn/rx
Traceback (most recent call last):
  File "/home/ubuntu/.local/lib/python3.6/site-packages/django/core/handlers/exception.py", line 34, in inner
    response = get_response(request)
  File "/home/ubuntu/.local/lib/python3.6/site-packages/django/core/handlers/base.py", line 115, in _get_response
    response = self.process_exception_by_middleware(e, request)
  File "/home/ubuntu/.local/lib/python3.6/site-packages/django/core/handlers/base.py", line 113, in _get_response
    response = wrapped_callback(request, *callback_args, **callback_kwargs)
  File "/home/ubuntu/.local/lib/python3.6/site-packages/django/views/decorators/csrf.py", line 54, in wrapped_view
    return view_func(*args, **kwargs)
  File "./users/views.py", line 98, in upload_tcn_rx
    user = User.objects.get(uuid=uuid)
  File "/home/ubuntu/.local/lib/python3.6/site-packages/django/db/models/manager.py", line 82, in manager_method
    return getattr(self.get_queryset(), name)(*args, **kwargs)
  File "/home/ubuntu/.local/lib/python3.6/site-packages/django/db/models/query.py", line 417, in get
    self.model._meta.object_name
users.models.User.DoesNotExist: User matching query does not exist.
2020-07-28 21:09:23,345 - ERROR: Internal Server Error: /api/upload/tcn/tx
Traceback (most recent call last):
  File "/home/ubuntu/.local/lib/python3.6/site-packages/django/core/handlers/exception.py", line 34, in inner
    response = get_response(request)
  File "/home/ubuntu/.local/lib/python3.6/site-packages/django/core/handlers/base.py", line 115, in _get_response
    response = self.process_exception_by_middleware(e, request)
  File "/home/ubuntu/.local/lib/python3.6/site-packages/django/core/handlers/base.py", line 113, in _get_response
    response = wrapped_callback(request, *callback_args, **callback_kwargs)
  File "/home/ubuntu/.local/lib/python3.6/site-packages/django/views/decorators/csrf.py", line 54, in wrapped_view
    return view_func(*args, **kwargs)
  File "./users/views.py", line 153, in upload_tcn_tx
    user = User.objects.get(uuid=uuid)
  File "/home/ubuntu/.local/lib/python3.6/site-packages/django/db/models/manager.py", line 82, in manager_method
    return getattr(self.get_queryset(), name)(*args, **kwargs)
  File "/home/ubuntu/.local/lib/python3.6/site-packages/django/db/models/query.py", line 417, in get
    self.model._meta.object_name
users.models.User.DoesNotExist: User matching query does not exist.
2020-07-28 21:54:56,736 - WARNING: Not Found: /favicon.ico
2020-07-28 22:13:41,767 - WARNING: Not Found: /apple-touch-icon-120x120-precomposed.png
2020-07-28 22:13:41,954 - WARNING: Not Found: /apple-touch-icon-120x120.png
2020-07-28 22:13:42,140 - WARNING: Not Found: /apple-touch-icon-precomposed.png
2020-07-28 22:13:42,336 - WARNING: Not Found: /apple-touch-icon.png
2020-07-28 22:13:42,531 - WARNING: Not Found: /favicon.ico
2020-07-29 00:37:47,952 - WARNING: Not Found: /favicon.ico
2020-07-29 01:08:56,792 - WARNING: Not Found: /favicon.ico
2020-07-29 10:43:19,277 - WARNING: Not Found: /favicon.ico
2020-07-29 12:39:15,452 - ERROR: Internal Server Error: /api/register
Traceback (most recent call last):
  File "/home/ubuntu/.local/lib/python3.6/site-packages/django/core/handlers/exception.py", line 34, in inner
    response = get_response(request)
  File "/home/ubuntu/.local/lib/python3.6/site-packages/django/utils/deprecation.py", line 93, in __call__
    response = self.process_request(request)
  File "/home/ubuntu/.local/lib/python3.6/site-packages/django/middleware/common.py", line 54, in process_request
    path = self.get_full_path_with_slash(request)
  File "/home/ubuntu/.local/lib/python3.6/site-packages/django/middleware/common.py", line 94, in get_full_path_with_slash
    'url': request.get_host() + new_path,
RuntimeError: You called this URL via POST, but the URL doesn't end in a slash and you have APPEND_SLASH set. Django can't redirect to the slash URL while maintaining POST data. Change your form to point to 10.118.127.58/api/register/ (note the trailing slash), or set APPEND_SLASH=False in your Django settings.
2020-07-29 12:56:35,280 - WARNING: Not Found: /favicon.ico
2020-07-29 14:59:16,533 - WARNING: Not Found: /favicon.ico
2020-07-29 16:34:31,670 - WARNING: Not Found: /favicon.ico
2020-07-31 12:22:11,528 - WARNING: Not Found: /favicon.ico
2020-08-21 15:18:55,031 - WARNING: Not Found: /robots.txt
