
2020-07-21 14:58:32,938 - WARNING: Not Found: /favicon.ico
2020-07-21 14:58:52,014 - WARNING: Not Found: /favicon.ico
2020-07-21 14:59:52,205 - WARNING: Not Found: /favicon.ico
2020-07-21 15:04:37,819 - WARNING: Not Found: /favicon.ico
2020-07-21 15:07:34,163 - WARNING: Not Found: /favicon.ico
2020-07-21 15:07:41,762 - WARNING: Not Found: /favicon.ico
2020-07-21 15:11:01,565 - WARNING: Not Found: /favicon.ico
2020-07-21 15:21:12,404 - WARNING: Not Found: /apple-touch-icon-precomposed.png
2020-07-21 15:21:12,406 - WARNING: Not Found: /apple-touch-icon.png
2020-07-21 15:21:12,415 - WARNING: Not Found: /favicon.ico
2020-07-21 15:24:19,900 - WARNING: Not Found: /favicon.ico
2020-07-21 15:25:41,428 - WARNING: Not Found: /favicon.ico
2020-07-21 15:28:49,203 - WARNING: Not Found: /favicon.ico
2020-07-21 15:28:58,124 - WARNING: Not Found: /apple-touch-icon.png
2020-07-21 15:28:58,124 - WARNING: Not Found: /apple-touch-icon-precomposed.png
2020-07-21 15:40:18,771 - WARNING: Not Found: /favicon.ico
2020-07-21 15:52:10,496 - WARNING: Not Found: /favicon.ico
2020-07-21 15:52:34,435 - WARNING: Not Found: /favicon.ico
2020-07-21 15:56:27,063 - ERROR: Internal Server Error: /api/upload/tcn/rx
Traceback (most recent call last):
  File "/home/ubuntu/.local/lib/python3.6/site-packages/django/core/handlers/exception.py", line 34, in inner
    response = get_response(request)
  File "/home/ubuntu/.local/lib/python3.6/site-packages/django/core/handlers/base.py", line 115, in _get_response
    response = self.process_exception_by_middleware(e, request)
  File "/home/ubuntu/.local/lib/python3.6/site-packages/django/core/handlers/base.py", line 113, in _get_response
    response = wrapped_callback(request, *callback_args, **callback_kwargs)
  File "/home/ubuntu/.local/lib/python3.6/site-packages/django/views/decorators/csrf.py", line 54, in wrapped_view
    return view_func(*args, **kwargs)
  File "./users/views.py", line 77, in upload_tcn_rx
    data = json.loads(request.body)
  File "/usr/lib/python3.6/json/__init__.py", line 354, in loads
    return _default_decoder.decode(s)
  File "/usr/lib/python3.6/json/decoder.py", line 339, in decode
    obj, end = self.raw_decode(s, idx=_w(s, 0).end())
  File "/usr/lib/python3.6/json/decoder.py", line 355, in raw_decode
    obj, end = self.scan_once(s, idx)
json.decoder.JSONDecodeError: Expecting ',' delimiter: line 1 column 2153330 (char 2153329)
2020-07-21 15:58:05,517 - ERROR: Internal Server Error: /api/update/exp_id
Traceback (most recent call last):
  File "/home/ubuntu/.local/lib/python3.6/site-packages/django/core/handlers/exception.py", line 34, in inner
    response = get_response(request)
  File "/home/ubuntu/.local/lib/python3.6/site-packages/django/core/handlers/base.py", line 115, in _get_response
    response = self.process_exception_by_middleware(e, request)
  File "/home/ubuntu/.local/lib/python3.6/site-packages/django/core/handlers/base.py", line 113, in _get_response
    response = wrapped_callback(request, *callback_args, **callback_kwargs)
  File "/home/ubuntu/.local/lib/python3.6/site-packages/django/views/decorators/csrf.py", line 54, in wrapped_view
    return view_func(*args, **kwargs)
  File "./users/views.py", line 204, in update_exp_id
    data = json.loads(request.body)
  File "/usr/lib/python3.6/json/__init__.py", line 354, in loads
    return _default_decoder.decode(s)
  File "/usr/lib/python3.6/json/decoder.py", line 339, in decode
    obj, end = self.raw_decode(s, idx=_w(s, 0).end())
  File "/usr/lib/python3.6/json/decoder.py", line 355, in raw_decode
    obj, end = self.scan_once(s, idx)
json.decoder.JSONDecodeError: Expecting ',' delimiter: line 2 column 16 (char 17)
2020-07-21 15:58:21,589 - INFO: Update Experiment ID: 0
2020-07-21 15:59:11,009 - ERROR: Internal Server Error: /api/upload/tcn/rx
Traceback (most recent call last):
  File "/home/ubuntu/.local/lib/python3.6/site-packages/django/core/handlers/exception.py", line 34, in inner
    response = get_response(request)
  File "/home/ubuntu/.local/lib/python3.6/site-packages/django/core/handlers/base.py", line 115, in _get_response
    response = self.process_exception_by_middleware(e, request)
  File "/home/ubuntu/.local/lib/python3.6/site-packages/django/core/handlers/base.py", line 113, in _get_response
    response = wrapped_callback(request, *callback_args, **callback_kwargs)
  File "/home/ubuntu/.local/lib/python3.6/site-packages/django/views/decorators/csrf.py", line 54, in wrapped_view
    return view_func(*args, **kwargs)
  File "./users/views.py", line 77, in upload_tcn_rx
    data = json.loads(request.body)
  File "/usr/lib/python3.6/json/__init__.py", line 354, in loads
    return _default_decoder.decode(s)
  File "/usr/lib/python3.6/json/decoder.py", line 339, in decode
    obj, end = self.raw_decode(s, idx=_w(s, 0).end())
  File "/usr/lib/python3.6/json/decoder.py", line 355, in raw_decode
    obj, end = self.scan_once(s, idx)
json.decoder.JSONDecodeError: Expecting ',' delimiter: line 1 column 4820177 (char 4820176)
2020-07-21 16:00:10,188 - INFO: Update Experiment ID: 0
2020-07-21 16:02:32,214 - INFO: Update Experiment ID: 0
2020-07-21 16:03:07,046 - INFO: Update Experiment ID: 1
2020-07-21 16:16:43,797 - INFO: Update Experiment ID: 2
2020-07-21 16:18:30,442 - ERROR: Internal Server Error: /api/upload/tcn/rx
Traceback (most recent call last):
  File "/home/ubuntu/.local/lib/python3.6/site-packages/django/core/handlers/exception.py", line 34, in inner
    response = get_response(request)
  File "/home/ubuntu/.local/lib/python3.6/site-packages/django/core/handlers/base.py", line 115, in _get_response
    response = self.process_exception_by_middleware(e, request)
  File "/home/ubuntu/.local/lib/python3.6/site-packages/django/core/handlers/base.py", line 113, in _get_response
    response = wrapped_callback(request, *callback_args, **callback_kwargs)
  File "/home/ubuntu/.local/lib/python3.6/site-packages/django/views/decorators/csrf.py", line 54, in wrapped_view
    return view_func(*args, **kwargs)
  File "./users/views.py", line 77, in upload_tcn_rx
    data = json.loads(request.body)
  File "/usr/lib/python3.6/json/__init__.py", line 354, in loads
    return _default_decoder.decode(s)
  File "/usr/lib/python3.6/json/decoder.py", line 339, in decode
    obj, end = self.raw_decode(s, idx=_w(s, 0).end())
  File "/usr/lib/python3.6/json/decoder.py", line 355, in raw_decode
    obj, end = self.scan_once(s, idx)
json.decoder.JSONDecodeError: Expecting ',' delimiter: line 1 column 2153330 (char 2153329)
2020-07-21 16:20:45,939 - INFO: Update Experiment ID: 3
2020-07-21 16:24:14,441 - ERROR: Internal Server Error: /api/upload/tcn/rx
Traceback (most recent call last):
  File "/home/ubuntu/.local/lib/python3.6/site-packages/django/core/handlers/exception.py", line 34, in inner
    response = get_response(request)
  File "/home/ubuntu/.local/lib/python3.6/site-packages/django/core/handlers/base.py", line 115, in _get_response
    response = self.process_exception_by_middleware(e, request)
  File "/home/ubuntu/.local/lib/python3.6/site-packages/django/core/handlers/base.py", line 113, in _get_response
    response = wrapped_callback(request, *callback_args, **callback_kwargs)
  File "/home/ubuntu/.local/lib/python3.6/site-packages/django/views/decorators/csrf.py", line 54, in wrapped_view
    return view_func(*args, **kwargs)
  File "./users/views.py", line 77, in upload_tcn_rx
    data = json.loads(request.body)
  File "/usr/lib/python3.6/json/__init__.py", line 354, in loads
    return _default_decoder.decode(s)
  File "/usr/lib/python3.6/json/decoder.py", line 339, in decode
    obj, end = self.raw_decode(s, idx=_w(s, 0).end())
  File "/usr/lib/python3.6/json/decoder.py", line 355, in raw_decode
    obj, end = self.scan_once(s, idx)
json.decoder.JSONDecodeError: Expecting ',' delimiter: line 1 column 2153330 (char 2153329)
2020-07-21 16:24:48,200 - INFO: Update Experiment ID: 4
2020-07-21 16:26:18,904 - ERROR: Internal Server Error: /api/upload/tcn/rx
Traceback (most recent call last):
  File "/home/ubuntu/.local/lib/python3.6/site-packages/django/core/handlers/exception.py", line 34, in inner
    response = get_response(request)
  File "/home/ubuntu/.local/lib/python3.6/site-packages/django/core/handlers/base.py", line 115, in _get_response
    response = self.process_exception_by_middleware(e, request)
  File "/home/ubuntu/.local/lib/python3.6/site-packages/django/core/handlers/base.py", line 113, in _get_response
    response = wrapped_callback(request, *callback_args, **callback_kwargs)
  File "/home/ubuntu/.local/lib/python3.6/site-packages/django/views/decorators/csrf.py", line 54, in wrapped_view
    return view_func(*args, **kwargs)
  File "./users/views.py", line 77, in upload_tcn_rx
    data = json.loads(request.body)
  File "/usr/lib/python3.6/json/__init__.py", line 354, in loads
    return _default_decoder.decode(s)
  File "/usr/lib/python3.6/json/decoder.py", line 339, in decode
    obj, end = self.raw_decode(s, idx=_w(s, 0).end())
  File "/usr/lib/python3.6/json/decoder.py", line 355, in raw_decode
    obj, end = self.scan_once(s, idx)
json.decoder.JSONDecodeError: Expecting ',' delimiter: line 1 column 2153330 (char 2153329)
2020-07-21 16:28:26,140 - WARNING: Not Found: /favicon.ico
2020-07-21 16:30:38,603 - INFO: Update Experiment ID: 5
2020-07-21 16:34:21,765 - INFO: Update Experiment ID: 6
2020-07-21 16:38:06,733 - INFO: Update Experiment ID: 7
2020-07-21 16:42:55,297 - INFO: Update Experiment ID: 8
2020-07-21 16:44:47,626 - WARNING: Not Found: /favicon.ico
2020-07-21 16:45:21,526 - ERROR: Internal Server Error: /api/upload/tcn/rx
Traceback (most recent call last):
  File "/home/ubuntu/.local/lib/python3.6/site-packages/django/core/handlers/exception.py", line 34, in inner
    response = get_response(request)
  File "/home/ubuntu/.local/lib/python3.6/site-packages/django/core/handlers/base.py", line 115, in _get_response
    response = self.process_exception_by_middleware(e, request)
  File "/home/ubuntu/.local/lib/python3.6/site-packages/django/core/handlers/base.py", line 113, in _get_response
    response = wrapped_callback(request, *callback_args, **callback_kwargs)
  File "/home/ubuntu/.local/lib/python3.6/site-packages/django/views/decorators/csrf.py", line 54, in wrapped_view
    return view_func(*args, **kwargs)
  File "./users/views.py", line 77, in upload_tcn_rx
    data = json.loads(request.body)
  File "/usr/lib/python3.6/json/__init__.py", line 354, in loads
    return _default_decoder.decode(s)
  File "/usr/lib/python3.6/json/decoder.py", line 339, in decode
    obj, end = self.raw_decode(s, idx=_w(s, 0).end())
  File "/usr/lib/python3.6/json/decoder.py", line 355, in raw_decode
    obj, end = self.scan_once(s, idx)
json.decoder.JSONDecodeError: Expecting ',' delimiter: line 1 column 2153330 (char 2153329)
2020-07-21 16:45:37,981 - INFO: Update Experiment ID: 9
2020-07-21 16:48:40,459 - ERROR: Internal Server Error: /api/upload/tcn/rx
Traceback (most recent call last):
  File "/home/ubuntu/.local/lib/python3.6/site-packages/django/core/handlers/exception.py", line 34, in inner
    response = get_response(request)
  File "/home/ubuntu/.local/lib/python3.6/site-packages/django/core/handlers/base.py", line 115, in _get_response
    response = self.process_exception_by_middleware(e, request)
  File "/home/ubuntu/.local/lib/python3.6/site-packages/django/core/handlers/base.py", line 113, in _get_response
    response = wrapped_callback(request, *callback_args, **callback_kwargs)
  File "/home/ubuntu/.local/lib/python3.6/site-packages/django/views/decorators/csrf.py", line 54, in wrapped_view
    return view_func(*args, **kwargs)
  File "./users/views.py", line 77, in upload_tcn_rx
    data = json.loads(request.body)
  File "/usr/lib/python3.6/json/__init__.py", line 354, in loads
    return _default_decoder.decode(s)
  File "/usr/lib/python3.6/json/decoder.py", line 339, in decode
    obj, end = self.raw_decode(s, idx=_w(s, 0).end())
  File "/usr/lib/python3.6/json/decoder.py", line 355, in raw_decode
    obj, end = self.scan_once(s, idx)
json.decoder.JSONDecodeError: Expecting ',' delimiter: line 1 column 2153330 (char 2153329)
2020-07-21 16:48:46,044 - INFO: Update Experiment ID: 10
2020-07-21 16:49:35,353 - WARNING: Not Found: /favicon.ico
2020-07-21 16:51:20,040 - ERROR: Internal Server Error: /api/upload/tcn/rx
Traceback (most recent call last):
  File "/home/ubuntu/.local/lib/python3.6/site-packages/django/core/handlers/exception.py", line 34, in inner
    response = get_response(request)
  File "/home/ubuntu/.local/lib/python3.6/site-packages/django/core/handlers/base.py", line 115, in _get_response
    response = self.process_exception_by_middleware(e, request)
  File "/home/ubuntu/.local/lib/python3.6/site-packages/django/core/handlers/base.py", line 113, in _get_response
    response = wrapped_callback(request, *callback_args, **callback_kwargs)
  File "/home/ubuntu/.local/lib/python3.6/site-packages/django/views/decorators/csrf.py", line 54, in wrapped_view
    return view_func(*args, **kwargs)
  File "./users/views.py", line 77, in upload_tcn_rx
    data = json.loads(request.body)
  File "/usr/lib/python3.6/json/__init__.py", line 354, in loads
    return _default_decoder.decode(s)
  File "/usr/lib/python3.6/json/decoder.py", line 339, in decode
    obj, end = self.raw_decode(s, idx=_w(s, 0).end())
  File "/usr/lib/python3.6/json/decoder.py", line 355, in raw_decode
    obj, end = self.scan_once(s, idx)
json.decoder.JSONDecodeError: Expecting ',' delimiter: line 1 column 2153330 (char 2153329)
2020-07-21 16:51:53,689 - INFO: Update Experiment ID: 11
2020-07-21 16:55:04,547 - ERROR: Internal Server Error: /api/upload/tcn/rx
Traceback (most recent call last):
  File "/home/ubuntu/.local/lib/python3.6/site-packages/django/core/handlers/exception.py", line 34, in inner
    response = get_response(request)
  File "/home/ubuntu/.local/lib/python3.6/site-packages/django/core/handlers/base.py", line 115, in _get_response
    response = self.process_exception_by_middleware(e, request)
  File "/home/ubuntu/.local/lib/python3.6/site-packages/django/core/handlers/base.py", line 113, in _get_response
    response = wrapped_callback(request, *callback_args, **callback_kwargs)
  File "/home/ubuntu/.local/lib/python3.6/site-packages/django/views/decorators/csrf.py", line 54, in wrapped_view
    return view_func(*args, **kwargs)
  File "./users/views.py", line 77, in upload_tcn_rx
    data = json.loads(request.body)
  File "/usr/lib/python3.6/json/__init__.py", line 354, in loads
    return _default_decoder.decode(s)
  File "/usr/lib/python3.6/json/decoder.py", line 339, in decode
    obj, end = self.raw_decode(s, idx=_w(s, 0).end())
  File "/usr/lib/python3.6/json/decoder.py", line 355, in raw_decode
    obj, end = self.scan_once(s, idx)
json.decoder.JSONDecodeError: Expecting ',' delimiter: line 1 column 2153330 (char 2153329)
2020-07-21 16:56:26,221 - INFO: Update Experiment ID: 12
2020-07-21 16:58:44,520 - INFO: Update Experiment ID: 13
2020-07-21 16:58:53,169 - ERROR: Internal Server Error: /api/upload/tcn/rx
Traceback (most recent call last):
  File "/home/ubuntu/.local/lib/python3.6/site-packages/django/core/handlers/exception.py", line 34, in inner
    response = get_response(request)
  File "/home/ubuntu/.local/lib/python3.6/site-packages/django/core/handlers/base.py", line 115, in _get_response
    response = self.process_exception_by_middleware(e, request)
  File "/home/ubuntu/.local/lib/python3.6/site-packages/django/core/handlers/base.py", line 113, in _get_response
    response = wrapped_callback(request, *callback_args, **callback_kwargs)
  File "/home/ubuntu/.local/lib/python3.6/site-packages/django/views/decorators/csrf.py", line 54, in wrapped_view
    return view_func(*args, **kwargs)
  File "./users/views.py", line 77, in upload_tcn_rx
    data = json.loads(request.body)
  File "/usr/lib/python3.6/json/__init__.py", line 354, in loads
    return _default_decoder.decode(s)
  File "/usr/lib/python3.6/json/decoder.py", line 339, in decode
    obj, end = self.raw_decode(s, idx=_w(s, 0).end())
  File "/usr/lib/python3.6/json/decoder.py", line 355, in raw_decode
    obj, end = self.scan_once(s, idx)
json.decoder.JSONDecodeError: Expecting ',' delimiter: line 1 column 2153330 (char 2153329)
2020-07-21 17:00:55,990 - ERROR: Internal Server Error: /api/upload/tcn/rx
Traceback (most recent call last):
  File "/home/ubuntu/.local/lib/python3.6/site-packages/django/core/handlers/exception.py", line 34, in inner
    response = get_response(request)
  File "/home/ubuntu/.local/lib/python3.6/site-packages/django/core/handlers/base.py", line 115, in _get_response
    response = self.process_exception_by_middleware(e, request)
  File "/home/ubuntu/.local/lib/python3.6/site-packages/django/core/handlers/base.py", line 113, in _get_response
    response = wrapped_callback(request, *callback_args, **callback_kwargs)
  File "/home/ubuntu/.local/lib/python3.6/site-packages/django/views/decorators/csrf.py", line 54, in wrapped_view
    return view_func(*args, **kwargs)
  File "./users/views.py", line 77, in upload_tcn_rx
    data = json.loads(request.body)
  File "/usr/lib/python3.6/json/__init__.py", line 354, in loads
    return _default_decoder.decode(s)
  File "/usr/lib/python3.6/json/decoder.py", line 339, in decode
    obj, end = self.raw_decode(s, idx=_w(s, 0).end())
  File "/usr/lib/python3.6/json/decoder.py", line 355, in raw_decode
    obj, end = self.scan_once(s, idx)
json.decoder.JSONDecodeError: Expecting ',' delimiter: line 1 column 2153330 (char 2153329)
2020-07-21 17:11:00,192 - INFO: Update Experiment ID: 14
2020-07-21 17:14:22,278 - ERROR: Internal Server Error: /api/upload/tcn/rx
Traceback (most recent call last):
  File "/home/ubuntu/.local/lib/python3.6/site-packages/django/core/handlers/exception.py", line 34, in inner
    response = get_response(request)
  File "/home/ubuntu/.local/lib/python3.6/site-packages/django/core/handlers/base.py", line 115, in _get_response
    response = self.process_exception_by_middleware(e, request)
  File "/home/ubuntu/.local/lib/python3.6/site-packages/django/core/handlers/base.py", line 113, in _get_response
    response = wrapped_callback(request, *callback_args, **callback_kwargs)
  File "/home/ubuntu/.local/lib/python3.6/site-packages/django/views/decorators/csrf.py", line 54, in wrapped_view
    return view_func(*args, **kwargs)
  File "./users/views.py", line 77, in upload_tcn_rx
    data = json.loads(request.body)
  File "/usr/lib/python3.6/json/__init__.py", line 354, in loads
    return _default_decoder.decode(s)
  File "/usr/lib/python3.6/json/decoder.py", line 339, in decode
    obj, end = self.raw_decode(s, idx=_w(s, 0).end())
  File "/usr/lib/python3.6/json/decoder.py", line 355, in raw_decode
    obj, end = self.scan_once(s, idx)
json.decoder.JSONDecodeError: Expecting ',' delimiter: line 1 column 2153330 (char 2153329)
2020-07-21 17:14:54,796 - INFO: Update Experiment ID: 15
2020-07-21 17:17:45,027 - INFO: Update Experiment ID: 16
2020-07-21 17:19:54,274 - INFO: Update Experiment ID: 16
2020-07-21 17:24:40,263 - INFO: Update Experiment ID: 17
2020-07-21 17:28:12,962 - INFO: Update Experiment ID: 18
2020-07-21 17:41:29,623 - INFO: Update Experiment ID: 19
2020-07-21 17:44:10,365 - INFO: Update Experiment ID: 20
2020-07-21 17:48:24,190 - INFO: Update Experiment ID: 21
2020-07-21 17:52:24,064 - INFO: Update Experiment ID: 22
2020-07-21 17:54:17,478 - INFO: Update Experiment ID: 23
2020-07-21 17:56:29,782 - INFO: Update Experiment ID: 24
2020-07-21 17:59:33,556 - INFO: Update Experiment ID: 25
2020-07-21 18:01:19,021 - INFO: Update Experiment ID: 26
2020-07-21 18:01:26,263 - INFO: Update Experiment ID: 26
2020-07-21 18:05:01,938 - INFO: Update Experiment ID: 27
2020-07-21 18:07:58,375 - INFO: Update Experiment ID: 28
2020-07-21 18:11:11,628 - INFO: Update Experiment ID: 29
2020-07-21 19:10:20,679 - WARNING: Not Found: /favicon.ico
2020-07-21 19:50:20,262 - WARNING: Not Found: /favicon.ico
2020-07-21 20:43:07,622 - WARNING: Not Found: /favicon.ico
2020-07-26 17:27:17,548 - WARNING: Not Found: /robots.txt
2020-07-26 17:27:18,779 - WARNING: Not Found: /favicon.ico
2020-07-26 17:28:48,980 - INFO: Update Experiment ID: 0
2020-07-26 17:29:09,522 - INFO: Update Experiment ID: 1
2020-07-26 17:29:17,316 - INFO: Update Experiment ID: 0
2020-07-26 18:42:45,512 - ERROR: Internal Server Error: /api/upload/tcn/tx
Traceback (most recent call last):
  File "/home/ubuntu/.local/lib/python3.6/site-packages/django/core/handlers/exception.py", line 34, in inner
    response = get_response(request)
  File "/home/ubuntu/.local/lib/python3.6/site-packages/django/core/handlers/base.py", line 115, in _get_response
    response = self.process_exception_by_middleware(e, request)
  File "/home/ubuntu/.local/lib/python3.6/site-packages/django/core/handlers/base.py", line 113, in _get_response
    response = wrapped_callback(request, *callback_args, **callback_kwargs)
  File "/home/ubuntu/.local/lib/python3.6/site-packages/django/views/decorators/csrf.py", line 54, in wrapped_view
    return view_func(*args, **kwargs)
  File "./users/views.py", line 135, in upload_tcn_tx
    user = User.objects.get(uuid=uuid)
  File "/home/ubuntu/.local/lib/python3.6/site-packages/django/db/models/manager.py", line 82, in manager_method
    return getattr(self.get_queryset(), name)(*args, **kwargs)
  File "/home/ubuntu/.local/lib/python3.6/site-packages/django/db/models/query.py", line 417, in get
    self.model._meta.object_name
users.models.User.DoesNotExist: User matching query does not exist.
2020-07-26 18:42:46,557 - ERROR: Internal Server Error: /api/upload/tcn/rx
Traceback (most recent call last):
  File "/home/ubuntu/.local/lib/python3.6/site-packages/django/core/handlers/exception.py", line 34, in inner
    response = get_response(request)
  File "/home/ubuntu/.local/lib/python3.6/site-packages/django/core/handlers/base.py", line 115, in _get_response
    response = self.process_exception_by_middleware(e, request)
  File "/home/ubuntu/.local/lib/python3.6/site-packages/django/core/handlers/base.py", line 113, in _get_response
    response = wrapped_callback(request, *callback_args, **callback_kwargs)
  File "/home/ubuntu/.local/lib/python3.6/site-packages/django/views/decorators/csrf.py", line 54, in wrapped_view
    return view_func(*args, **kwargs)
  File "./users/views.py", line 80, in upload_tcn_rx
    user = User.objects.get(uuid=uuid)
  File "/home/ubuntu/.local/lib/python3.6/site-packages/django/db/models/manager.py", line 82, in manager_method
    return getattr(self.get_queryset(), name)(*args, **kwargs)
  File "/home/ubuntu/.local/lib/python3.6/site-packages/django/db/models/query.py", line 417, in get
    self.model._meta.object_name
users.models.User.DoesNotExist: User matching query does not exist.
2020-07-26 18:43:33,589 - ERROR: Internal Server Error: /api/upload/tcn/tx
Traceback (most recent call last):
  File "/home/ubuntu/.local/lib/python3.6/site-packages/django/core/handlers/exception.py", line 34, in inner
    response = get_response(request)
  File "/home/ubuntu/.local/lib/python3.6/site-packages/django/core/handlers/base.py", line 115, in _get_response
    response = self.process_exception_by_middleware(e, request)
  File "/home/ubuntu/.local/lib/python3.6/site-packages/django/core/handlers/base.py", line 113, in _get_response
    response = wrapped_callback(request, *callback_args, **callback_kwargs)
  File "/home/ubuntu/.local/lib/python3.6/site-packages/django/views/decorators/csrf.py", line 54, in wrapped_view
    return view_func(*args, **kwargs)
  File "./users/views.py", line 135, in upload_tcn_tx
    user = User.objects.get(uuid=uuid)
  File "/home/ubuntu/.local/lib/python3.6/site-packages/django/db/models/manager.py", line 82, in manager_method
    return getattr(self.get_queryset(), name)(*args, **kwargs)
  File "/home/ubuntu/.local/lib/python3.6/site-packages/django/db/models/query.py", line 417, in get
    self.model._meta.object_name
users.models.User.DoesNotExist: User matching query does not exist.
2020-07-26 18:43:34,641 - ERROR: Internal Server Error: /api/upload/tcn/rx
Traceback (most recent call last):
  File "/home/ubuntu/.local/lib/python3.6/site-packages/django/core/handlers/exception.py", line 34, in inner
    response = get_response(request)
  File "/home/ubuntu/.local/lib/python3.6/site-packages/django/core/handlers/base.py", line 115, in _get_response
    response = self.process_exception_by_middleware(e, request)
  File "/home/ubuntu/.local/lib/python3.6/site-packages/django/core/handlers/base.py", line 113, in _get_response
    response = wrapped_callback(request, *callback_args, **callback_kwargs)
  File "/home/ubuntu/.local/lib/python3.6/site-packages/django/views/decorators/csrf.py", line 54, in wrapped_view
    return view_func(*args, **kwargs)
  File "./users/views.py", line 80, in upload_tcn_rx
    user = User.objects.get(uuid=uuid)
  File "/home/ubuntu/.local/lib/python3.6/site-packages/django/db/models/manager.py", line 82, in manager_method
    return getattr(self.get_queryset(), name)(*args, **kwargs)
  File "/home/ubuntu/.local/lib/python3.6/site-packages/django/db/models/query.py", line 417, in get
    self.model._meta.object_name
users.models.User.DoesNotExist: User matching query does not exist.
2020-07-26 18:43:47,713 - ERROR: Internal Server Error: /api/upload/tcn/tx
Traceback (most recent call last):
  File "/home/ubuntu/.local/lib/python3.6/site-packages/django/core/handlers/exception.py", line 34, in inner
    response = get_response(request)
  File "/home/ubuntu/.local/lib/python3.6/site-packages/django/core/handlers/base.py", line 115, in _get_response
    response = self.process_exception_by_middleware(e, request)
  File "/home/ubuntu/.local/lib/python3.6/site-packages/django/core/handlers/base.py", line 113, in _get_response
    response = wrapped_callback(request, *callback_args, **callback_kwargs)
  File "/home/ubuntu/.local/lib/python3.6/site-packages/django/views/decorators/csrf.py", line 54, in wrapped_view
    return view_func(*args, **kwargs)
  File "./users/views.py", line 135, in upload_tcn_tx
    user = User.objects.get(uuid=uuid)
  File "/home/ubuntu/.local/lib/python3.6/site-packages/django/db/models/manager.py", line 82, in manager_method
    return getattr(self.get_queryset(), name)(*args, **kwargs)
  File "/home/ubuntu/.local/lib/python3.6/site-packages/django/db/models/query.py", line 417, in get
    self.model._meta.object_name
users.models.User.DoesNotExist: User matching query does not exist.
2020-07-26 18:43:48,889 - ERROR: Internal Server Error: /api/upload/tcn/rx
Traceback (most recent call last):
  File "/home/ubuntu/.local/lib/python3.6/site-packages/django/core/handlers/exception.py", line 34, in inner
    response = get_response(request)
  File "/home/ubuntu/.local/lib/python3.6/site-packages/django/core/handlers/base.py", line 115, in _get_response
    response = self.process_exception_by_middleware(e, request)
  File "/home/ubuntu/.local/lib/python3.6/site-packages/django/core/handlers/base.py", line 113, in _get_response
    response = wrapped_callback(request, *callback_args, **callback_kwargs)
  File "/home/ubuntu/.local/lib/python3.6/site-packages/django/views/decorators/csrf.py", line 54, in wrapped_view
    return view_func(*args, **kwargs)
  File "./users/views.py", line 80, in upload_tcn_rx
    user = User.objects.get(uuid=uuid)
  File "/home/ubuntu/.local/lib/python3.6/site-packages/django/db/models/manager.py", line 82, in manager_method
    return getattr(self.get_queryset(), name)(*args, **kwargs)
  File "/home/ubuntu/.local/lib/python3.6/site-packages/django/db/models/query.py", line 417, in get
    self.model._meta.object_name
users.models.User.DoesNotExist: User matching query does not exist.
2020-07-26 18:43:57,698 - ERROR: Internal Server Error: /api/upload/tcn/tx
Traceback (most recent call last):
  File "/home/ubuntu/.local/lib/python3.6/site-packages/django/core/handlers/exception.py", line 34, in inner
    response = get_response(request)
  File "/home/ubuntu/.local/lib/python3.6/site-packages/django/core/handlers/base.py", line 115, in _get_response
    response = self.process_exception_by_middleware(e, request)
  File "/home/ubuntu/.local/lib/python3.6/site-packages/django/core/handlers/base.py", line 113, in _get_response
    response = wrapped_callback(request, *callback_args, **callback_kwargs)
  File "/home/ubuntu/.local/lib/python3.6/site-packages/django/views/decorators/csrf.py", line 54, in wrapped_view
    return view_func(*args, **kwargs)
  File "./users/views.py", line 135, in upload_tcn_tx
    user = User.objects.get(uuid=uuid)
  File "/home/ubuntu/.local/lib/python3.6/site-packages/django/db/models/manager.py", line 82, in manager_method
    return getattr(self.get_queryset(), name)(*args, **kwargs)
  File "/home/ubuntu/.local/lib/python3.6/site-packages/django/db/models/query.py", line 417, in get
    self.model._meta.object_name
users.models.User.DoesNotExist: User matching query does not exist.
2020-07-26 18:43:58,874 - ERROR: Internal Server Error: /api/upload/tcn/rx
Traceback (most recent call last):
  File "/home/ubuntu/.local/lib/python3.6/site-packages/django/core/handlers/exception.py", line 34, in inner
    response = get_response(request)
  File "/home/ubuntu/.local/lib/python3.6/site-packages/django/core/handlers/base.py", line 115, in _get_response
    response = self.process_exception_by_middleware(e, request)
  File "/home/ubuntu/.local/lib/python3.6/site-packages/django/core/handlers/base.py", line 113, in _get_response
    response = wrapped_callback(request, *callback_args, **callback_kwargs)
  File "/home/ubuntu/.local/lib/python3.6/site-packages/django/views/decorators/csrf.py", line 54, in wrapped_view
    return view_func(*args, **kwargs)
  File "./users/views.py", line 80, in upload_tcn_rx
    user = User.objects.get(uuid=uuid)
  File "/home/ubuntu/.local/lib/python3.6/site-packages/django/db/models/manager.py", line 82, in manager_method
    return getattr(self.get_queryset(), name)(*args, **kwargs)
  File "/home/ubuntu/.local/lib/python3.6/site-packages/django/db/models/query.py", line 417, in get
    self.model._meta.object_name
users.models.User.DoesNotExist: User matching query does not exist.
2020-07-26 18:44:08,781 - ERROR: Internal Server Error: /api/upload/tcn/tx
Traceback (most recent call last):
  File "/home/ubuntu/.local/lib/python3.6/site-packages/django/core/handlers/exception.py", line 34, in inner
    response = get_response(request)
  File "/home/ubuntu/.local/lib/python3.6/site-packages/django/core/handlers/base.py", line 115, in _get_response
    response = self.process_exception_by_middleware(e, request)
  File "/home/ubuntu/.local/lib/python3.6/site-packages/django/core/handlers/base.py", line 113, in _get_response
    response = wrapped_callback(request, *callback_args, **callback_kwargs)
  File "/home/ubuntu/.local/lib/python3.6/site-packages/django/views/decorators/csrf.py", line 54, in wrapped_view
    return view_func(*args, **kwargs)
  File "./users/views.py", line 135, in upload_tcn_tx
    user = User.objects.get(uuid=uuid)
  File "/home/ubuntu/.local/lib/python3.6/site-packages/django/db/models/manager.py", line 82, in manager_method
    return getattr(self.get_queryset(), name)(*args, **kwargs)
  File "/home/ubuntu/.local/lib/python3.6/site-packages/django/db/models/query.py", line 417, in get
    self.model._meta.object_name
users.models.User.DoesNotExist: User matching query does not exist.
2020-07-26 18:44:09,942 - ERROR: Internal Server Error: /api/upload/tcn/rx
Traceback (most recent call last):
  File "/home/ubuntu/.local/lib/python3.6/site-packages/django/core/handlers/exception.py", line 34, in inner
    response = get_response(request)
  File "/home/ubuntu/.local/lib/python3.6/site-packages/django/core/handlers/base.py", line 115, in _get_response
    response = self.process_exception_by_middleware(e, request)
  File "/home/ubuntu/.local/lib/python3.6/site-packages/django/core/handlers/base.py", line 113, in _get_response
    response = wrapped_callback(request, *callback_args, **callback_kwargs)
  File "/home/ubuntu/.local/lib/python3.6/site-packages/django/views/decorators/csrf.py", line 54, in wrapped_view
    return view_func(*args, **kwargs)
  File "./users/views.py", line 80, in upload_tcn_rx
    user = User.objects.get(uuid=uuid)
  File "/home/ubuntu/.local/lib/python3.6/site-packages/django/db/models/manager.py", line 82, in manager_method
    return getattr(self.get_queryset(), name)(*args, **kwargs)
  File "/home/ubuntu/.local/lib/python3.6/site-packages/django/db/models/query.py", line 417, in get
    self.model._meta.object_name
users.models.User.DoesNotExist: User matching query does not exist.
2020-07-26 18:44:19,029 - ERROR: Internal Server Error: /api/upload/tcn/tx
Traceback (most recent call last):
  File "/home/ubuntu/.local/lib/python3.6/site-packages/django/core/handlers/exception.py", line 34, in inner
    response = get_response(request)
  File "/home/ubuntu/.local/lib/python3.6/site-packages/django/core/handlers/base.py", line 115, in _get_response
    response = self.process_exception_by_middleware(e, request)
  File "/home/ubuntu/.local/lib/python3.6/site-packages/django/core/handlers/base.py", line 113, in _get_response
    response = wrapped_callback(request, *callback_args, **callback_kwargs)
  File "/home/ubuntu/.local/lib/python3.6/site-packages/django/views/decorators/csrf.py", line 54, in wrapped_view
    return view_func(*args, **kwargs)
  File "./users/views.py", line 135, in upload_tcn_tx
    user = User.objects.get(uuid=uuid)
  File "/home/ubuntu/.local/lib/python3.6/site-packages/django/db/models/manager.py", line 82, in manager_method
    return getattr(self.get_queryset(), name)(*args, **kwargs)
  File "/home/ubuntu/.local/lib/python3.6/site-packages/django/db/models/query.py", line 417, in get
    self.model._meta.object_name
users.models.User.DoesNotExist: User matching query does not exist.
2020-07-26 18:44:20,247 - ERROR: Internal Server Error: /api/upload/tcn/rx
Traceback (most recent call last):
  File "/home/ubuntu/.local/lib/python3.6/site-packages/django/core/handlers/exception.py", line 34, in inner
    response = get_response(request)
  File "/home/ubuntu/.local/lib/python3.6/site-packages/django/core/handlers/base.py", line 115, in _get_response
    response = self.process_exception_by_middleware(e, request)
  File "/home/ubuntu/.local/lib/python3.6/site-packages/django/core/handlers/base.py", line 113, in _get_response
    response = wrapped_callback(request, *callback_args, **callback_kwargs)
  File "/home/ubuntu/.local/lib/python3.6/site-packages/django/views/decorators/csrf.py", line 54, in wrapped_view
    return view_func(*args, **kwargs)
  File "./users/views.py", line 80, in upload_tcn_rx
    user = User.objects.get(uuid=uuid)
  File "/home/ubuntu/.local/lib/python3.6/site-packages/django/db/models/manager.py", line 82, in manager_method
    return getattr(self.get_queryset(), name)(*args, **kwargs)
  File "/home/ubuntu/.local/lib/python3.6/site-packages/django/db/models/query.py", line 417, in get
    self.model._meta.object_name
users.models.User.DoesNotExist: User matching query does not exist.
2020-07-26 18:44:33,534 - ERROR: Internal Server Error: /api/upload/tcn/tx
Traceback (most recent call last):
  File "/home/ubuntu/.local/lib/python3.6/site-packages/django/core/handlers/exception.py", line 34, in inner
    response = get_response(request)
  File "/home/ubuntu/.local/lib/python3.6/site-packages/django/core/handlers/base.py", line 115, in _get_response
    response = self.process_exception_by_middleware(e, request)
  File "/home/ubuntu/.local/lib/python3.6/site-packages/django/core/handlers/base.py", line 113, in _get_response
    response = wrapped_callback(request, *callback_args, **callback_kwargs)
  File "/home/ubuntu/.local/lib/python3.6/site-packages/django/views/decorators/csrf.py", line 54, in wrapped_view
    return view_func(*args, **kwargs)
  File "./users/views.py", line 135, in upload_tcn_tx
    user = User.objects.get(uuid=uuid)
  File "/home/ubuntu/.local/lib/python3.6/site-packages/django/db/models/manager.py", line 82, in manager_method
    return getattr(self.get_queryset(), name)(*args, **kwargs)
  File "/home/ubuntu/.local/lib/python3.6/site-packages/django/db/models/query.py", line 417, in get
    self.model._meta.object_name
users.models.User.DoesNotExist: User matching query does not exist.
2020-07-26 18:44:34,733 - ERROR: Internal Server Error: /api/upload/tcn/rx
Traceback (most recent call last):
  File "/home/ubuntu/.local/lib/python3.6/site-packages/django/core/handlers/exception.py", line 34, in inner
    response = get_response(request)
  File "/home/ubuntu/.local/lib/python3.6/site-packages/django/core/handlers/base.py", line 115, in _get_response
    response = self.process_exception_by_middleware(e, request)
  File "/home/ubuntu/.local/lib/python3.6/site-packages/django/core/handlers/base.py", line 113, in _get_response
    response = wrapped_callback(request, *callback_args, **callback_kwargs)
  File "/home/ubuntu/.local/lib/python3.6/site-packages/django/views/decorators/csrf.py", line 54, in wrapped_view
    return view_func(*args, **kwargs)
  File "./users/views.py", line 80, in upload_tcn_rx
    user = User.objects.get(uuid=uuid)
  File "/home/ubuntu/.local/lib/python3.6/site-packages/django/db/models/manager.py", line 82, in manager_method
    return getattr(self.get_queryset(), name)(*args, **kwargs)
  File "/home/ubuntu/.local/lib/python3.6/site-packages/django/db/models/query.py", line 417, in get
    self.model._meta.object_name
users.models.User.DoesNotExist: User matching query does not exist.
2020-07-26 18:44:42,540 - ERROR: Internal Server Error: /api/upload/tcn/tx
Traceback (most recent call last):
  File "/home/ubuntu/.local/lib/python3.6/site-packages/django/core/handlers/exception.py", line 34, in inner
    response = get_response(request)
  File "/home/ubuntu/.local/lib/python3.6/site-packages/django/core/handlers/base.py", line 115, in _get_response
    response = self.process_exception_by_middleware(e, request)
  File "/home/ubuntu/.local/lib/python3.6/site-packages/django/core/handlers/base.py", line 113, in _get_response
    response = wrapped_callback(request, *callback_args, **callback_kwargs)
  File "/home/ubuntu/.local/lib/python3.6/site-packages/django/views/decorators/csrf.py", line 54, in wrapped_view
    return view_func(*args, **kwargs)
  File "./users/views.py", line 135, in upload_tcn_tx
    user = User.objects.get(uuid=uuid)
  File "/home/ubuntu/.local/lib/python3.6/site-packages/django/db/models/manager.py", line 82, in manager_method
    return getattr(self.get_queryset(), name)(*args, **kwargs)
  File "/home/ubuntu/.local/lib/python3.6/site-packages/django/db/models/query.py", line 417, in get
    self.model._meta.object_name
users.models.User.DoesNotExist: User matching query does not exist.
2020-07-26 18:44:43,746 - ERROR: Internal Server Error: /api/upload/tcn/rx
Traceback (most recent call last):
  File "/home/ubuntu/.local/lib/python3.6/site-packages/django/core/handlers/exception.py", line 34, in inner
    response = get_response(request)
  File "/home/ubuntu/.local/lib/python3.6/site-packages/django/core/handlers/base.py", line 115, in _get_response
    response = self.process_exception_by_middleware(e, request)
  File "/home/ubuntu/.local/lib/python3.6/site-packages/django/core/handlers/base.py", line 113, in _get_response
    response = wrapped_callback(request, *callback_args, **callback_kwargs)
  File "/home/ubuntu/.local/lib/python3.6/site-packages/django/views/decorators/csrf.py", line 54, in wrapped_view
    return view_func(*args, **kwargs)
  File "./users/views.py", line 80, in upload_tcn_rx
    user = User.objects.get(uuid=uuid)
  File "/home/ubuntu/.local/lib/python3.6/site-packages/django/db/models/manager.py", line 82, in manager_method
    return getattr(self.get_queryset(), name)(*args, **kwargs)
  File "/home/ubuntu/.local/lib/python3.6/site-packages/django/db/models/query.py", line 417, in get
    self.model._meta.object_name
users.models.User.DoesNotExist: User matching query does not exist.
2020-07-26 18:44:52,327 - ERROR: Internal Server Error: /api/upload/tcn/tx
Traceback (most recent call last):
  File "/home/ubuntu/.local/lib/python3.6/site-packages/django/core/handlers/exception.py", line 34, in inner
    response = get_response(request)
  File "/home/ubuntu/.local/lib/python3.6/site-packages/django/core/handlers/base.py", line 115, in _get_response
    response = self.process_exception_by_middleware(e, request)
  File "/home/ubuntu/.local/lib/python3.6/site-packages/django/core/handlers/base.py", line 113, in _get_response
    response = wrapped_callback(request, *callback_args, **callback_kwargs)
  File "/home/ubuntu/.local/lib/python3.6/site-packages/django/views/decorators/csrf.py", line 54, in wrapped_view
    return view_func(*args, **kwargs)
  File "./users/views.py", line 135, in upload_tcn_tx
    user = User.objects.get(uuid=uuid)
  File "/home/ubuntu/.local/lib/python3.6/site-packages/django/db/models/manager.py", line 82, in manager_method
    return getattr(self.get_queryset(), name)(*args, **kwargs)
  File "/home/ubuntu/.local/lib/python3.6/site-packages/django/db/models/query.py", line 417, in get
    self.model._meta.object_name
users.models.User.DoesNotExist: User matching query does not exist.
2020-07-26 18:44:53,570 - ERROR: Internal Server Error: /api/upload/tcn/rx
Traceback (most recent call last):
  File "/home/ubuntu/.local/lib/python3.6/site-packages/django/core/handlers/exception.py", line 34, in inner
    response = get_response(request)
  File "/home/ubuntu/.local/lib/python3.6/site-packages/django/core/handlers/base.py", line 115, in _get_response
    response = self.process_exception_by_middleware(e, request)
  File "/home/ubuntu/.local/lib/python3.6/site-packages/django/core/handlers/base.py", line 113, in _get_response
    response = wrapped_callback(request, *callback_args, **callback_kwargs)
  File "/home/ubuntu/.local/lib/python3.6/site-packages/django/views/decorators/csrf.py", line 54, in wrapped_view
    return view_func(*args, **kwargs)
  File "./users/views.py", line 80, in upload_tcn_rx
    user = User.objects.get(uuid=uuid)
  File "/home/ubuntu/.local/lib/python3.6/site-packages/django/db/models/manager.py", line 82, in manager_method
    return getattr(self.get_queryset(), name)(*args, **kwargs)
  File "/home/ubuntu/.local/lib/python3.6/site-packages/django/db/models/query.py", line 417, in get
    self.model._meta.object_name
users.models.User.DoesNotExist: User matching query does not exist.
2020-07-26 18:46:05,333 - ERROR: Internal Server Error: /api/upload/tcn/tx
Traceback (most recent call last):
  File "/home/ubuntu/.local/lib/python3.6/site-packages/django/core/handlers/exception.py", line 34, in inner
    response = get_response(request)
  File "/home/ubuntu/.local/lib/python3.6/site-packages/django/core/handlers/base.py", line 115, in _get_response
    response = self.process_exception_by_middleware(e, request)
  File "/home/ubuntu/.local/lib/python3.6/site-packages/django/core/handlers/base.py", line 113, in _get_response
    response = wrapped_callback(request, *callback_args, **callback_kwargs)
  File "/home/ubuntu/.local/lib/python3.6/site-packages/django/views/decorators/csrf.py", line 54, in wrapped_view
    return view_func(*args, **kwargs)
  File "./users/views.py", line 135, in upload_tcn_tx
    user = User.objects.get(uuid=uuid)
  File "/home/ubuntu/.local/lib/python3.6/site-packages/django/db/models/manager.py", line 82, in manager_method
    return getattr(self.get_queryset(), name)(*args, **kwargs)
  File "/home/ubuntu/.local/lib/python3.6/site-packages/django/db/models/query.py", line 417, in get
    self.model._meta.object_name
users.models.User.DoesNotExist: User matching query does not exist.
2020-07-26 18:46:06,727 - ERROR: Internal Server Error: /api/upload/tcn/rx
Traceback (most recent call last):
  File "/home/ubuntu/.local/lib/python3.6/site-packages/django/core/handlers/exception.py", line 34, in inner
    response = get_response(request)
  File "/home/ubuntu/.local/lib/python3.6/site-packages/django/core/handlers/base.py", line 115, in _get_response
    response = self.process_exception_by_middleware(e, request)
  File "/home/ubuntu/.local/lib/python3.6/site-packages/django/core/handlers/base.py", line 113, in _get_response
    response = wrapped_callback(request, *callback_args, **callback_kwargs)
  File "/home/ubuntu/.local/lib/python3.6/site-packages/django/views/decorators/csrf.py", line 54, in wrapped_view
    return view_func(*args, **kwargs)
  File "./users/views.py", line 80, in upload_tcn_rx
    user = User.objects.get(uuid=uuid)
  File "/home/ubuntu/.local/lib/python3.6/site-packages/django/db/models/manager.py", line 82, in manager_method
    return getattr(self.get_queryset(), name)(*args, **kwargs)
  File "/home/ubuntu/.local/lib/python3.6/site-packages/django/db/models/query.py", line 417, in get
    self.model._meta.object_name
users.models.User.DoesNotExist: User matching query does not exist.
2020-07-26 18:46:13,273 - ERROR: Internal Server Error: /api/upload/tcn/tx
Traceback (most recent call last):
  File "/home/ubuntu/.local/lib/python3.6/site-packages/django/core/handlers/exception.py", line 34, in inner
    response = get_response(request)
  File "/home/ubuntu/.local/lib/python3.6/site-packages/django/core/handlers/base.py", line 115, in _get_response
    response = self.process_exception_by_middleware(e, request)
  File "/home/ubuntu/.local/lib/python3.6/site-packages/django/core/handlers/base.py", line 113, in _get_response
    response = wrapped_callback(request, *callback_args, **callback_kwargs)
  File "/home/ubuntu/.local/lib/python3.6/site-packages/django/views/decorators/csrf.py", line 54, in wrapped_view
    return view_func(*args, **kwargs)
  File "./users/views.py", line 135, in upload_tcn_tx
    user = User.objects.get(uuid=uuid)
  File "/home/ubuntu/.local/lib/python3.6/site-packages/django/db/models/manager.py", line 82, in manager_method
    return getattr(self.get_queryset(), name)(*args, **kwargs)
  File "/home/ubuntu/.local/lib/python3.6/site-packages/django/db/models/query.py", line 417, in get
    self.model._meta.object_name
users.models.User.DoesNotExist: User matching query does not exist.
2020-07-26 18:46:14,698 - ERROR: Internal Server Error: /api/upload/tcn/rx
Traceback (most recent call last):
  File "/home/ubuntu/.local/lib/python3.6/site-packages/django/core/handlers/exception.py", line 34, in inner
    response = get_response(request)
  File "/home/ubuntu/.local/lib/python3.6/site-packages/django/core/handlers/base.py", line 115, in _get_response
    response = self.process_exception_by_middleware(e, request)
  File "/home/ubuntu/.local/lib/python3.6/site-packages/django/core/handlers/base.py", line 113, in _get_response
    response = wrapped_callback(request, *callback_args, **callback_kwargs)
  File "/home/ubuntu/.local/lib/python3.6/site-packages/django/views/decorators/csrf.py", line 54, in wrapped_view
    return view_func(*args, **kwargs)
  File "./users/views.py", line 80, in upload_tcn_rx
    user = User.objects.get(uuid=uuid)
  File "/home/ubuntu/.local/lib/python3.6/site-packages/django/db/models/manager.py", line 82, in manager_method
    return getattr(self.get_queryset(), name)(*args, **kwargs)
  File "/home/ubuntu/.local/lib/python3.6/site-packages/django/db/models/query.py", line 417, in get
    self.model._meta.object_name
users.models.User.DoesNotExist: User matching query does not exist.
2020-07-26 18:46:22,941 - ERROR: Internal Server Error: /api/upload/tcn/tx
Traceback (most recent call last):
  File "/home/ubuntu/.local/lib/python3.6/site-packages/django/core/handlers/exception.py", line 34, in inner
    response = get_response(request)
  File "/home/ubuntu/.local/lib/python3.6/site-packages/django/core/handlers/base.py", line 115, in _get_response
    response = self.process_exception_by_middleware(e, request)
  File "/home/ubuntu/.local/lib/python3.6/site-packages/django/core/handlers/base.py", line 113, in _get_response
    response = wrapped_callback(request, *callback_args, **callback_kwargs)
  File "/home/ubuntu/.local/lib/python3.6/site-packages/django/views/decorators/csrf.py", line 54, in wrapped_view
    return view_func(*args, **kwargs)
  File "./users/views.py", line 135, in upload_tcn_tx
    user = User.objects.get(uuid=uuid)
  File "/home/ubuntu/.local/lib/python3.6/site-packages/django/db/models/manager.py", line 82, in manager_method
    return getattr(self.get_queryset(), name)(*args, **kwargs)
  File "/home/ubuntu/.local/lib/python3.6/site-packages/django/db/models/query.py", line 417, in get
    self.model._meta.object_name
users.models.User.DoesNotExist: User matching query does not exist.
2020-07-26 18:46:24,199 - ERROR: Internal Server Error: /api/upload/tcn/rx
Traceback (most recent call last):
  File "/home/ubuntu/.local/lib/python3.6/site-packages/django/core/handlers/exception.py", line 34, in inner
    response = get_response(request)
  File "/home/ubuntu/.local/lib/python3.6/site-packages/django/core/handlers/base.py", line 115, in _get_response
    response = self.process_exception_by_middleware(e, request)
  File "/home/ubuntu/.local/lib/python3.6/site-packages/django/core/handlers/base.py", line 113, in _get_response
    response = wrapped_callback(request, *callback_args, **callback_kwargs)
  File "/home/ubuntu/.local/lib/python3.6/site-packages/django/views/decorators/csrf.py", line 54, in wrapped_view
    return view_func(*args, **kwargs)
  File "./users/views.py", line 80, in upload_tcn_rx
    user = User.objects.get(uuid=uuid)
  File "/home/ubuntu/.local/lib/python3.6/site-packages/django/db/models/manager.py", line 82, in manager_method
    return getattr(self.get_queryset(), name)(*args, **kwargs)
  File "/home/ubuntu/.local/lib/python3.6/site-packages/django/db/models/query.py", line 417, in get
    self.model._meta.object_name
users.models.User.DoesNotExist: User matching query does not exist.
2020-07-26 18:46:33,271 - ERROR: Internal Server Error: /api/upload/tcn/tx
Traceback (most recent call last):
  File "/home/ubuntu/.local/lib/python3.6/site-packages/django/core/handlers/exception.py", line 34, in inner
    response = get_response(request)
  File "/home/ubuntu/.local/lib/python3.6/site-packages/django/core/handlers/base.py", line 115, in _get_response
    response = self.process_exception_by_middleware(e, request)
  File "/home/ubuntu/.local/lib/python3.6/site-packages/django/core/handlers/base.py", line 113, in _get_response
    response = wrapped_callback(request, *callback_args, **callback_kwargs)
  File "/home/ubuntu/.local/lib/python3.6/site-packages/django/views/decorators/csrf.py", line 54, in wrapped_view
    return view_func(*args, **kwargs)
  File "./users/views.py", line 135, in upload_tcn_tx
    user = User.objects.get(uuid=uuid)
  File "/home/ubuntu/.local/lib/python3.6/site-packages/django/db/models/manager.py", line 82, in manager_method
    return getattr(self.get_queryset(), name)(*args, **kwargs)
  File "/home/ubuntu/.local/lib/python3.6/site-packages/django/db/models/query.py", line 417, in get
    self.model._meta.object_name
users.models.User.DoesNotExist: User matching query does not exist.
2020-07-26 18:46:34,675 - ERROR: Internal Server Error: /api/upload/tcn/rx
Traceback (most recent call last):
  File "/home/ubuntu/.local/lib/python3.6/site-packages/django/core/handlers/exception.py", line 34, in inner
    response = get_response(request)
  File "/home/ubuntu/.local/lib/python3.6/site-packages/django/core/handlers/base.py", line 115, in _get_response
    response = self.process_exception_by_middleware(e, request)
  File "/home/ubuntu/.local/lib/python3.6/site-packages/django/core/handlers/base.py", line 113, in _get_response
    response = wrapped_callback(request, *callback_args, **callback_kwargs)
  File "/home/ubuntu/.local/lib/python3.6/site-packages/django/views/decorators/csrf.py", line 54, in wrapped_view
    return view_func(*args, **kwargs)
  File "./users/views.py", line 80, in upload_tcn_rx
    user = User.objects.get(uuid=uuid)
  File "/home/ubuntu/.local/lib/python3.6/site-packages/django/db/models/manager.py", line 82, in manager_method
    return getattr(self.get_queryset(), name)(*args, **kwargs)
  File "/home/ubuntu/.local/lib/python3.6/site-packages/django/db/models/query.py", line 417, in get
    self.model._meta.object_name
users.models.User.DoesNotExist: User matching query does not exist.
2020-07-26 18:57:41,955 - ERROR: Internal Server Error: /api/upload/tcn/tx
Traceback (most recent call last):
  File "/home/ubuntu/.local/lib/python3.6/site-packages/django/core/handlers/exception.py", line 34, in inner
    response = get_response(request)
  File "/home/ubuntu/.local/lib/python3.6/site-packages/django/core/handlers/base.py", line 115, in _get_response
    response = self.process_exception_by_middleware(e, request)
  File "/home/ubuntu/.local/lib/python3.6/site-packages/django/core/handlers/base.py", line 113, in _get_response
    response = wrapped_callback(request, *callback_args, **callback_kwargs)
  File "/home/ubuntu/.local/lib/python3.6/site-packages/django/views/decorators/csrf.py", line 54, in wrapped_view
    return view_func(*args, **kwargs)
  File "./users/views.py", line 135, in upload_tcn_tx
    user = User.objects.get(uuid=uuid)
  File "/home/ubuntu/.local/lib/python3.6/site-packages/django/db/models/manager.py", line 82, in manager_method
    return getattr(self.get_queryset(), name)(*args, **kwargs)
  File "/home/ubuntu/.local/lib/python3.6/site-packages/django/db/models/query.py", line 417, in get
    self.model._meta.object_name
users.models.User.DoesNotExist: User matching query does not exist.
2020-07-26 18:57:43,587 - ERROR: Internal Server Error: /api/upload/tcn/rx
Traceback (most recent call last):
  File "/home/ubuntu/.local/lib/python3.6/site-packages/django/core/handlers/exception.py", line 34, in inner
    response = get_response(request)
  File "/home/ubuntu/.local/lib/python3.6/site-packages/django/core/handlers/base.py", line 115, in _get_response
    response = self.process_exception_by_middleware(e, request)
  File "/home/ubuntu/.local/lib/python3.6/site-packages/django/core/handlers/base.py", line 113, in _get_response
    response = wrapped_callback(request, *callback_args, **callback_kwargs)
  File "/home/ubuntu/.local/lib/python3.6/site-packages/django/views/decorators/csrf.py", line 54, in wrapped_view
    return view_func(*args, **kwargs)
  File "./users/views.py", line 80, in upload_tcn_rx
    user = User.objects.get(uuid=uuid)
  File "/home/ubuntu/.local/lib/python3.6/site-packages/django/db/models/manager.py", line 82, in manager_method
    return getattr(self.get_queryset(), name)(*args, **kwargs)
  File "/home/ubuntu/.local/lib/python3.6/site-packages/django/db/models/query.py", line 417, in get
    self.model._meta.object_name
users.models.User.DoesNotExist: User matching query does not exist.
2020-07-26 18:57:45,269 - ERROR: Internal Server Error: /api/upload/tcn/tx
Traceback (most recent call last):
  File "/home/ubuntu/.local/lib/python3.6/site-packages/django/core/handlers/exception.py", line 34, in inner
    response = get_response(request)
  File "/home/ubuntu/.local/lib/python3.6/site-packages/django/core/handlers/base.py", line 115, in _get_response
    response = self.process_exception_by_middleware(e, request)
  File "/home/ubuntu/.local/lib/python3.6/site-packages/django/core/handlers/base.py", line 113, in _get_response
    response = wrapped_callback(request, *callback_args, **callback_kwargs)
  File "/home/ubuntu/.local/lib/python3.6/site-packages/django/views/decorators/csrf.py", line 54, in wrapped_view
    return view_func(*args, **kwargs)
  File "./users/views.py", line 135, in upload_tcn_tx
    user = User.objects.get(uuid=uuid)
  File "/home/ubuntu/.local/lib/python3.6/site-packages/django/db/models/manager.py", line 82, in manager_method
    return getattr(self.get_queryset(), name)(*args, **kwargs)
  File "/home/ubuntu/.local/lib/python3.6/site-packages/django/db/models/query.py", line 417, in get
    self.model._meta.object_name
users.models.User.DoesNotExist: User matching query does not exist.
2020-07-26 18:57:47,096 - ERROR: Internal Server Error: /api/upload/tcn/rx
Traceback (most recent call last):
  File "/home/ubuntu/.local/lib/python3.6/site-packages/django/core/handlers/exception.py", line 34, in inner
    response = get_response(request)
  File "/home/ubuntu/.local/lib/python3.6/site-packages/django/core/handlers/base.py", line 115, in _get_response
    response = self.process_exception_by_middleware(e, request)
  File "/home/ubuntu/.local/lib/python3.6/site-packages/django/core/handlers/base.py", line 113, in _get_response
    response = wrapped_callback(request, *callback_args, **callback_kwargs)
  File "/home/ubuntu/.local/lib/python3.6/site-packages/django/views/decorators/csrf.py", line 54, in wrapped_view
    return view_func(*args, **kwargs)
  File "./users/views.py", line 80, in upload_tcn_rx
    user = User.objects.get(uuid=uuid)
  File "/home/ubuntu/.local/lib/python3.6/site-packages/django/db/models/manager.py", line 82, in manager_method
    return getattr(self.get_queryset(), name)(*args, **kwargs)
  File "/home/ubuntu/.local/lib/python3.6/site-packages/django/db/models/query.py", line 417, in get
    self.model._meta.object_name
users.models.User.DoesNotExist: User matching query does not exist.
2020-07-26 18:57:48,592 - ERROR: Internal Server Error: /api/upload/tcn/tx
Traceback (most recent call last):
  File "/home/ubuntu/.local/lib/python3.6/site-packages/django/core/handlers/exception.py", line 34, in inner
    response = get_response(request)
  File "/home/ubuntu/.local/lib/python3.6/site-packages/django/core/handlers/base.py", line 115, in _get_response
    response = self.process_exception_by_middleware(e, request)
  File "/home/ubuntu/.local/lib/python3.6/site-packages/django/core/handlers/base.py", line 113, in _get_response
    response = wrapped_callback(request, *callback_args, **callback_kwargs)
  File "/home/ubuntu/.local/lib/python3.6/site-packages/django/views/decorators/csrf.py", line 54, in wrapped_view
    return view_func(*args, **kwargs)
  File "./users/views.py", line 135, in upload_tcn_tx
    user = User.objects.get(uuid=uuid)
  File "/home/ubuntu/.local/lib/python3.6/site-packages/django/db/models/manager.py", line 82, in manager_method
    return getattr(self.get_queryset(), name)(*args, **kwargs)
  File "/home/ubuntu/.local/lib/python3.6/site-packages/django/db/models/query.py", line 417, in get
    self.model._meta.object_name
users.models.User.DoesNotExist: User matching query does not exist.
2020-07-26 18:57:50,347 - ERROR: Internal Server Error: /api/upload/tcn/rx
Traceback (most recent call last):
  File "/home/ubuntu/.local/lib/python3.6/site-packages/django/core/handlers/exception.py", line 34, in inner
    response = get_response(request)
  File "/home/ubuntu/.local/lib/python3.6/site-packages/django/core/handlers/base.py", line 115, in _get_response
    response = self.process_exception_by_middleware(e, request)
  File "/home/ubuntu/.local/lib/python3.6/site-packages/django/core/handlers/base.py", line 113, in _get_response
    response = wrapped_callback(request, *callback_args, **callback_kwargs)
  File "/home/ubuntu/.local/lib/python3.6/site-packages/django/views/decorators/csrf.py", line 54, in wrapped_view
    return view_func(*args, **kwargs)
  File "./users/views.py", line 80, in upload_tcn_rx
    user = User.objects.get(uuid=uuid)
  File "/home/ubuntu/.local/lib/python3.6/site-packages/django/db/models/manager.py", line 82, in manager_method
    return getattr(self.get_queryset(), name)(*args, **kwargs)
  File "/home/ubuntu/.local/lib/python3.6/site-packages/django/db/models/query.py", line 417, in get
    self.model._meta.object_name
users.models.User.DoesNotExist: User matching query does not exist.
2020-07-26 18:57:52,234 - ERROR: Internal Server Error: /api/upload/tcn/tx
Traceback (most recent call last):
  File "/home/ubuntu/.local/lib/python3.6/site-packages/django/core/handlers/exception.py", line 34, in inner
    response = get_response(request)
  File "/home/ubuntu/.local/lib/python3.6/site-packages/django/core/handlers/base.py", line 115, in _get_response
    response = self.process_exception_by_middleware(e, request)
  File "/home/ubuntu/.local/lib/python3.6/site-packages/django/core/handlers/base.py", line 113, in _get_response
    response = wrapped_callback(request, *callback_args, **callback_kwargs)
  File "/home/ubuntu/.local/lib/python3.6/site-packages/django/views/decorators/csrf.py", line 54, in wrapped_view
    return view_func(*args, **kwargs)
  File "./users/views.py", line 135, in upload_tcn_tx
    user = User.objects.get(uuid=uuid)
  File "/home/ubuntu/.local/lib/python3.6/site-packages/django/db/models/manager.py", line 82, in manager_method
    return getattr(self.get_queryset(), name)(*args, **kwargs)
  File "/home/ubuntu/.local/lib/python3.6/site-packages/django/db/models/query.py", line 417, in get
    self.model._meta.object_name
users.models.User.DoesNotExist: User matching query does not exist.
2020-07-26 18:57:53,931 - ERROR: Internal Server Error: /api/upload/tcn/rx
Traceback (most recent call last):
  File "/home/ubuntu/.local/lib/python3.6/site-packages/django/core/handlers/exception.py", line 34, in inner
    response = get_response(request)
  File "/home/ubuntu/.local/lib/python3.6/site-packages/django/core/handlers/base.py", line 115, in _get_response
    response = self.process_exception_by_middleware(e, request)
  File "/home/ubuntu/.local/lib/python3.6/site-packages/django/core/handlers/base.py", line 113, in _get_response
    response = wrapped_callback(request, *callback_args, **callback_kwargs)
  File "/home/ubuntu/.local/lib/python3.6/site-packages/django/views/decorators/csrf.py", line 54, in wrapped_view
    return view_func(*args, **kwargs)
  File "./users/views.py", line 80, in upload_tcn_rx
    user = User.objects.get(uuid=uuid)
  File "/home/ubuntu/.local/lib/python3.6/site-packages/django/db/models/manager.py", line 82, in manager_method
    return getattr(self.get_queryset(), name)(*args, **kwargs)
  File "/home/ubuntu/.local/lib/python3.6/site-packages/django/db/models/query.py", line 417, in get
    self.model._meta.object_name
users.models.User.DoesNotExist: User matching query does not exist.
2020-07-26 18:57:55,203 - ERROR: Internal Server Error: /api/upload/tcn/tx
Traceback (most recent call last):
  File "/home/ubuntu/.local/lib/python3.6/site-packages/django/core/handlers/exception.py", line 34, in inner
    response = get_response(request)
  File "/home/ubuntu/.local/lib/python3.6/site-packages/django/core/handlers/base.py", line 115, in _get_response
    response = self.process_exception_by_middleware(e, request)
  File "/home/ubuntu/.local/lib/python3.6/site-packages/django/core/handlers/base.py", line 113, in _get_response
    response = wrapped_callback(request, *callback_args, **callback_kwargs)
  File "/home/ubuntu/.local/lib/python3.6/site-packages/django/views/decorators/csrf.py", line 54, in wrapped_view
    return view_func(*args, **kwargs)
  File "./users/views.py", line 135, in upload_tcn_tx
    user = User.objects.get(uuid=uuid)
  File "/home/ubuntu/.local/lib/python3.6/site-packages/django/db/models/manager.py", line 82, in manager_method
    return getattr(self.get_queryset(), name)(*args, **kwargs)
  File "/home/ubuntu/.local/lib/python3.6/site-packages/django/db/models/query.py", line 417, in get
    self.model._meta.object_name
users.models.User.DoesNotExist: User matching query does not exist.
2020-07-26 18:57:56,683 - ERROR: Internal Server Error: /api/upload/tcn/rx
Traceback (most recent call last):
  File "/home/ubuntu/.local/lib/python3.6/site-packages/django/core/handlers/exception.py", line 34, in inner
    response = get_response(request)
  File "/home/ubuntu/.local/lib/python3.6/site-packages/django/core/handlers/base.py", line 115, in _get_response
    response = self.process_exception_by_middleware(e, request)
  File "/home/ubuntu/.local/lib/python3.6/site-packages/django/core/handlers/base.py", line 113, in _get_response
    response = wrapped_callback(request, *callback_args, **callback_kwargs)
  File "/home/ubuntu/.local/lib/python3.6/site-packages/django/views/decorators/csrf.py", line 54, in wrapped_view
    return view_func(*args, **kwargs)
  File "./users/views.py", line 80, in upload_tcn_rx
    user = User.objects.get(uuid=uuid)
  File "/home/ubuntu/.local/lib/python3.6/site-packages/django/db/models/manager.py", line 82, in manager_method
    return getattr(self.get_queryset(), name)(*args, **kwargs)
  File "/home/ubuntu/.local/lib/python3.6/site-packages/django/db/models/query.py", line 417, in get
    self.model._meta.object_name
users.models.User.DoesNotExist: User matching query does not exist.
2020-07-26 18:57:57,960 - ERROR: Internal Server Error: /api/upload/tcn/tx
Traceback (most recent call last):
  File "/home/ubuntu/.local/lib/python3.6/site-packages/django/core/handlers/exception.py", line 34, in inner
    response = get_response(request)
  File "/home/ubuntu/.local/lib/python3.6/site-packages/django/core/handlers/base.py", line 115, in _get_response
    response = self.process_exception_by_middleware(e, request)
  File "/home/ubuntu/.local/lib/python3.6/site-packages/django/core/handlers/base.py", line 113, in _get_response
    response = wrapped_callback(request, *callback_args, **callback_kwargs)
  File "/home/ubuntu/.local/lib/python3.6/site-packages/django/views/decorators/csrf.py", line 54, in wrapped_view
    return view_func(*args, **kwargs)
  File "./users/views.py", line 135, in upload_tcn_tx
    user = User.objects.get(uuid=uuid)
  File "/home/ubuntu/.local/lib/python3.6/site-packages/django/db/models/manager.py", line 82, in manager_method
    return getattr(self.get_queryset(), name)(*args, **kwargs)
  File "/home/ubuntu/.local/lib/python3.6/site-packages/django/db/models/query.py", line 417, in get
    self.model._meta.object_name
users.models.User.DoesNotExist: User matching query does not exist.
2020-07-26 18:57:59,451 - ERROR: Internal Server Error: /api/upload/tcn/rx
Traceback (most recent call last):
  File "/home/ubuntu/.local/lib/python3.6/site-packages/django/core/handlers/exception.py", line 34, in inner
    response = get_response(request)
  File "/home/ubuntu/.local/lib/python3.6/site-packages/django/core/handlers/base.py", line 115, in _get_response
    response = self.process_exception_by_middleware(e, request)
  File "/home/ubuntu/.local/lib/python3.6/site-packages/django/core/handlers/base.py", line 113, in _get_response
    response = wrapped_callback(request, *callback_args, **callback_kwargs)
  File "/home/ubuntu/.local/lib/python3.6/site-packages/django/views/decorators/csrf.py", line 54, in wrapped_view
    return view_func(*args, **kwargs)
  File "./users/views.py", line 80, in upload_tcn_rx
    user = User.objects.get(uuid=uuid)
  File "/home/ubuntu/.local/lib/python3.6/site-packages/django/db/models/manager.py", line 82, in manager_method
    return getattr(self.get_queryset(), name)(*args, **kwargs)
  File "/home/ubuntu/.local/lib/python3.6/site-packages/django/db/models/query.py", line 417, in get
    self.model._meta.object_name
users.models.User.DoesNotExist: User matching query does not exist.
2020-07-26 18:58:01,336 - ERROR: Internal Server Error: /api/upload/tcn/tx
Traceback (most recent call last):
  File "/home/ubuntu/.local/lib/python3.6/site-packages/django/core/handlers/exception.py", line 34, in inner
    response = get_response(request)
  File "/home/ubuntu/.local/lib/python3.6/site-packages/django/core/handlers/base.py", line 115, in _get_response
    response = self.process_exception_by_middleware(e, request)
  File "/home/ubuntu/.local/lib/python3.6/site-packages/django/core/handlers/base.py", line 113, in _get_response
    response = wrapped_callback(request, *callback_args, **callback_kwargs)
  File "/home/ubuntu/.local/lib/python3.6/site-packages/django/views/decorators/csrf.py", line 54, in wrapped_view
    return view_func(*args, **kwargs)
  File "./users/views.py", line 135, in upload_tcn_tx
    user = User.objects.get(uuid=uuid)
  File "/home/ubuntu/.local/lib/python3.6/site-packages/django/db/models/manager.py", line 82, in manager_method
    return getattr(self.get_queryset(), name)(*args, **kwargs)
  File "/home/ubuntu/.local/lib/python3.6/site-packages/django/db/models/query.py", line 417, in get
    self.model._meta.object_name
users.models.User.DoesNotExist: User matching query does not exist.
2020-07-26 18:58:02,834 - ERROR: Internal Server Error: /api/upload/tcn/rx
Traceback (most recent call last):
  File "/home/ubuntu/.local/lib/python3.6/site-packages/django/core/handlers/exception.py", line 34, in inner
    response = get_response(request)
  File "/home/ubuntu/.local/lib/python3.6/site-packages/django/core/handlers/base.py", line 115, in _get_response
    response = self.process_exception_by_middleware(e, request)
  File "/home/ubuntu/.local/lib/python3.6/site-packages/django/core/handlers/base.py", line 113, in _get_response
    response = wrapped_callback(request, *callback_args, **callback_kwargs)
  File "/home/ubuntu/.local/lib/python3.6/site-packages/django/views/decorators/csrf.py", line 54, in wrapped_view
    return view_func(*args, **kwargs)
  File "./users/views.py", line 80, in upload_tcn_rx
    user = User.objects.get(uuid=uuid)
  File "/home/ubuntu/.local/lib/python3.6/site-packages/django/db/models/manager.py", line 82, in manager_method
    return getattr(self.get_queryset(), name)(*args, **kwargs)
  File "/home/ubuntu/.local/lib/python3.6/site-packages/django/db/models/query.py", line 417, in get
    self.model._meta.object_name
users.models.User.DoesNotExist: User matching query does not exist.
2020-07-26 18:58:04,260 - ERROR: Internal Server Error: /api/upload/tcn/tx
Traceback (most recent call last):
  File "/home/ubuntu/.local/lib/python3.6/site-packages/django/core/handlers/exception.py", line 34, in inner
    response = get_response(request)
  File "/home/ubuntu/.local/lib/python3.6/site-packages/django/core/handlers/base.py", line 115, in _get_response
    response = self.process_exception_by_middleware(e, request)
  File "/home/ubuntu/.local/lib/python3.6/site-packages/django/core/handlers/base.py", line 113, in _get_response
    response = wrapped_callback(request, *callback_args, **callback_kwargs)
  File "/home/ubuntu/.local/lib/python3.6/site-packages/django/views/decorators/csrf.py", line 54, in wrapped_view
    return view_func(*args, **kwargs)
  File "./users/views.py", line 135, in upload_tcn_tx
    user = User.objects.get(uuid=uuid)
  File "/home/ubuntu/.local/lib/python3.6/site-packages/django/db/models/manager.py", line 82, in manager_method
    return getattr(self.get_queryset(), name)(*args, **kwargs)
  File "/home/ubuntu/.local/lib/python3.6/site-packages/django/db/models/query.py", line 417, in get
    self.model._meta.object_name
users.models.User.DoesNotExist: User matching query does not exist.
2020-07-26 18:58:06,359 - ERROR: Internal Server Error: /api/upload/tcn/rx
Traceback (most recent call last):
  File "/home/ubuntu/.local/lib/python3.6/site-packages/django/core/handlers/exception.py", line 34, in inner
    response = get_response(request)
  File "/home/ubuntu/.local/lib/python3.6/site-packages/django/core/handlers/base.py", line 115, in _get_response
    response = self.process_exception_by_middleware(e, request)
  File "/home/ubuntu/.local/lib/python3.6/site-packages/django/core/handlers/base.py", line 113, in _get_response
    response = wrapped_callback(request, *callback_args, **callback_kwargs)
  File "/home/ubuntu/.local/lib/python3.6/site-packages/django/views/decorators/csrf.py", line 54, in wrapped_view
    return view_func(*args, **kwargs)
  File "./users/views.py", line 80, in upload_tcn_rx
    user = User.objects.get(uuid=uuid)
  File "/home/ubuntu/.local/lib/python3.6/site-packages/django/db/models/manager.py", line 82, in manager_method
    return getattr(self.get_queryset(), name)(*args, **kwargs)
  File "/home/ubuntu/.local/lib/python3.6/site-packages/django/db/models/query.py", line 417, in get
    self.model._meta.object_name
users.models.User.DoesNotExist: User matching query does not exist.
2020-07-26 18:58:07,322 - ERROR: Internal Server Error: /api/upload/tcn/tx
Traceback (most recent call last):
  File "/home/ubuntu/.local/lib/python3.6/site-packages/django/core/handlers/exception.py", line 34, in inner
    response = get_response(request)
  File "/home/ubuntu/.local/lib/python3.6/site-packages/django/core/handlers/base.py", line 115, in _get_response
    response = self.process_exception_by_middleware(e, request)
  File "/home/ubuntu/.local/lib/python3.6/site-packages/django/core/handlers/base.py", line 113, in _get_response
    response = wrapped_callback(request, *callback_args, **callback_kwargs)
  File "/home/ubuntu/.local/lib/python3.6/site-packages/django/views/decorators/csrf.py", line 54, in wrapped_view
    return view_func(*args, **kwargs)
  File "./users/views.py", line 135, in upload_tcn_tx
    user = User.objects.get(uuid=uuid)
  File "/home/ubuntu/.local/lib/python3.6/site-packages/django/db/models/manager.py", line 82, in manager_method
    return getattr(self.get_queryset(), name)(*args, **kwargs)
  File "/home/ubuntu/.local/lib/python3.6/site-packages/django/db/models/query.py", line 417, in get
    self.model._meta.object_name
users.models.User.DoesNotExist: User matching query does not exist.
2020-07-26 18:58:08,932 - ERROR: Internal Server Error: /api/upload/tcn/rx
Traceback (most recent call last):
  File "/home/ubuntu/.local/lib/python3.6/site-packages/django/core/handlers/exception.py", line 34, in inner
    response = get_response(request)
  File "/home/ubuntu/.local/lib/python3.6/site-packages/django/core/handlers/base.py", line 115, in _get_response
    response = self.process_exception_by_middleware(e, request)
  File "/home/ubuntu/.local/lib/python3.6/site-packages/django/core/handlers/base.py", line 113, in _get_response
    response = wrapped_callback(request, *callback_args, **callback_kwargs)
  File "/home/ubuntu/.local/lib/python3.6/site-packages/django/views/decorators/csrf.py", line 54, in wrapped_view
    return view_func(*args, **kwargs)
  File "./users/views.py", line 80, in upload_tcn_rx
    user = User.objects.get(uuid=uuid)
  File "/home/ubuntu/.local/lib/python3.6/site-packages/django/db/models/manager.py", line 82, in manager_method
    return getattr(self.get_queryset(), name)(*args, **kwargs)
  File "/home/ubuntu/.local/lib/python3.6/site-packages/django/db/models/query.py", line 417, in get
    self.model._meta.object_name
users.models.User.DoesNotExist: User matching query does not exist.
2020-07-26 18:58:10,481 - ERROR: Internal Server Error: /api/upload/tcn/tx
Traceback (most recent call last):
  File "/home/ubuntu/.local/lib/python3.6/site-packages/django/core/handlers/exception.py", line 34, in inner
    response = get_response(request)
  File "/home/ubuntu/.local/lib/python3.6/site-packages/django/core/handlers/base.py", line 115, in _get_response
    response = self.process_exception_by_middleware(e, request)
  File "/home/ubuntu/.local/lib/python3.6/site-packages/django/core/handlers/base.py", line 113, in _get_response
    response = wrapped_callback(request, *callback_args, **callback_kwargs)
  File "/home/ubuntu/.local/lib/python3.6/site-packages/django/views/decorators/csrf.py", line 54, in wrapped_view
    return view_func(*args, **kwargs)
  File "./users/views.py", line 135, in upload_tcn_tx
    user = User.objects.get(uuid=uuid)
  File "/home/ubuntu/.local/lib/python3.6/site-packages/django/db/models/manager.py", line 82, in manager_method
    return getattr(self.get_queryset(), name)(*args, **kwargs)
  File "/home/ubuntu/.local/lib/python3.6/site-packages/django/db/models/query.py", line 417, in get
    self.model._meta.object_name
users.models.User.DoesNotExist: User matching query does not exist.
2020-07-26 18:58:12,045 - ERROR: Internal Server Error: /api/upload/tcn/rx
Traceback (most recent call last):
  File "/home/ubuntu/.local/lib/python3.6/site-packages/django/core/handlers/exception.py", line 34, in inner
    response = get_response(request)
  File "/home/ubuntu/.local/lib/python3.6/site-packages/django/core/handlers/base.py", line 115, in _get_response
    response = self.process_exception_by_middleware(e, request)
  File "/home/ubuntu/.local/lib/python3.6/site-packages/django/core/handlers/base.py", line 113, in _get_response
    response = wrapped_callback(request, *callback_args, **callback_kwargs)
  File "/home/ubuntu/.local/lib/python3.6/site-packages/django/views/decorators/csrf.py", line 54, in wrapped_view
    return view_func(*args, **kwargs)
  File "./users/views.py", line 80, in upload_tcn_rx
    user = User.objects.get(uuid=uuid)
  File "/home/ubuntu/.local/lib/python3.6/site-packages/django/db/models/manager.py", line 82, in manager_method
    return getattr(self.get_queryset(), name)(*args, **kwargs)
  File "/home/ubuntu/.local/lib/python3.6/site-packages/django/db/models/query.py", line 417, in get
    self.model._meta.object_name
users.models.User.DoesNotExist: User matching query does not exist.
2020-07-26 18:58:13,684 - ERROR: Internal Server Error: /api/upload/tcn/tx
Traceback (most recent call last):
  File "/home/ubuntu/.local/lib/python3.6/site-packages/django/core/handlers/exception.py", line 34, in inner
    response = get_response(request)
  File "/home/ubuntu/.local/lib/python3.6/site-packages/django/core/handlers/base.py", line 115, in _get_response
    response = self.process_exception_by_middleware(e, request)
  File "/home/ubuntu/.local/lib/python3.6/site-packages/django/core/handlers/base.py", line 113, in _get_response
    response = wrapped_callback(request, *callback_args, **callback_kwargs)
  File "/home/ubuntu/.local/lib/python3.6/site-packages/django/views/decorators/csrf.py", line 54, in wrapped_view
    return view_func(*args, **kwargs)
  File "./users/views.py", line 135, in upload_tcn_tx
    user = User.objects.get(uuid=uuid)
  File "/home/ubuntu/.local/lib/python3.6/site-packages/django/db/models/manager.py", line 82, in manager_method
    return getattr(self.get_queryset(), name)(*args, **kwargs)
  File "/home/ubuntu/.local/lib/python3.6/site-packages/django/db/models/query.py", line 417, in get
    self.model._meta.object_name
users.models.User.DoesNotExist: User matching query does not exist.
2020-07-26 18:58:15,607 - ERROR: Internal Server Error: /api/upload/tcn/rx
Traceback (most recent call last):
  File "/home/ubuntu/.local/lib/python3.6/site-packages/django/core/handlers/exception.py", line 34, in inner
    response = get_response(request)
  File "/home/ubuntu/.local/lib/python3.6/site-packages/django/core/handlers/base.py", line 115, in _get_response
    response = self.process_exception_by_middleware(e, request)
  File "/home/ubuntu/.local/lib/python3.6/site-packages/django/core/handlers/base.py", line 113, in _get_response
    response = wrapped_callback(request, *callback_args, **callback_kwargs)
  File "/home/ubuntu/.local/lib/python3.6/site-packages/django/views/decorators/csrf.py", line 54, in wrapped_view
    return view_func(*args, **kwargs)
  File "./users/views.py", line 80, in upload_tcn_rx
    user = User.objects.get(uuid=uuid)
  File "/home/ubuntu/.local/lib/python3.6/site-packages/django/db/models/manager.py", line 82, in manager_method
    return getattr(self.get_queryset(), name)(*args, **kwargs)
  File "/home/ubuntu/.local/lib/python3.6/site-packages/django/db/models/query.py", line 417, in get
    self.model._meta.object_name
users.models.User.DoesNotExist: User matching query does not exist.
2020-07-26 18:58:16,698 - ERROR: Internal Server Error: /api/upload/tcn/tx
Traceback (most recent call last):
  File "/home/ubuntu/.local/lib/python3.6/site-packages/django/core/handlers/exception.py", line 34, in inner
    response = get_response(request)
  File "/home/ubuntu/.local/lib/python3.6/site-packages/django/core/handlers/base.py", line 115, in _get_response
    response = self.process_exception_by_middleware(e, request)
  File "/home/ubuntu/.local/lib/python3.6/site-packages/django/core/handlers/base.py", line 113, in _get_response
    response = wrapped_callback(request, *callback_args, **callback_kwargs)
  File "/home/ubuntu/.local/lib/python3.6/site-packages/django/views/decorators/csrf.py", line 54, in wrapped_view
    return view_func(*args, **kwargs)
  File "./users/views.py", line 135, in upload_tcn_tx
    user = User.objects.get(uuid=uuid)
  File "/home/ubuntu/.local/lib/python3.6/site-packages/django/db/models/manager.py", line 82, in manager_method
    return getattr(self.get_queryset(), name)(*args, **kwargs)
  File "/home/ubuntu/.local/lib/python3.6/site-packages/django/db/models/query.py", line 417, in get
    self.model._meta.object_name
users.models.User.DoesNotExist: User matching query does not exist.
2020-07-26 18:58:18,364 - ERROR: Internal Server Error: /api/upload/tcn/rx
Traceback (most recent call last):
  File "/home/ubuntu/.local/lib/python3.6/site-packages/django/core/handlers/exception.py", line 34, in inner
    response = get_response(request)
  File "/home/ubuntu/.local/lib/python3.6/site-packages/django/core/handlers/base.py", line 115, in _get_response
    response = self.process_exception_by_middleware(e, request)
  File "/home/ubuntu/.local/lib/python3.6/site-packages/django/core/handlers/base.py", line 113, in _get_response
    response = wrapped_callback(request, *callback_args, **callback_kwargs)
  File "/home/ubuntu/.local/lib/python3.6/site-packages/django/views/decorators/csrf.py", line 54, in wrapped_view
    return view_func(*args, **kwargs)
  File "./users/views.py", line 80, in upload_tcn_rx
    user = User.objects.get(uuid=uuid)
  File "/home/ubuntu/.local/lib/python3.6/site-packages/django/db/models/manager.py", line 82, in manager_method
    return getattr(self.get_queryset(), name)(*args, **kwargs)
  File "/home/ubuntu/.local/lib/python3.6/site-packages/django/db/models/query.py", line 417, in get
    self.model._meta.object_name
users.models.User.DoesNotExist: User matching query does not exist.
2020-07-26 18:58:19,658 - ERROR: Internal Server Error: /api/upload/tcn/tx
Traceback (most recent call last):
  File "/home/ubuntu/.local/lib/python3.6/site-packages/django/core/handlers/exception.py", line 34, in inner
    response = get_response(request)
  File "/home/ubuntu/.local/lib/python3.6/site-packages/django/core/handlers/base.py", line 115, in _get_response
    response = self.process_exception_by_middleware(e, request)
  File "/home/ubuntu/.local/lib/python3.6/site-packages/django/core/handlers/base.py", line 113, in _get_response
    response = wrapped_callback(request, *callback_args, **callback_kwargs)
  File "/home/ubuntu/.local/lib/python3.6/site-packages/django/views/decorators/csrf.py", line 54, in wrapped_view
    return view_func(*args, **kwargs)
  File "./users/views.py", line 135, in upload_tcn_tx
    user = User.objects.get(uuid=uuid)
  File "/home/ubuntu/.local/lib/python3.6/site-packages/django/db/models/manager.py", line 82, in manager_method
    return getattr(self.get_queryset(), name)(*args, **kwargs)
  File "/home/ubuntu/.local/lib/python3.6/site-packages/django/db/models/query.py", line 417, in get
    self.model._meta.object_name
users.models.User.DoesNotExist: User matching query does not exist.
2020-07-26 18:58:21,109 - ERROR: Internal Server Error: /api/upload/tcn/rx
Traceback (most recent call last):
  File "/home/ubuntu/.local/lib/python3.6/site-packages/django/core/handlers/exception.py", line 34, in inner
    response = get_response(request)
  File "/home/ubuntu/.local/lib/python3.6/site-packages/django/core/handlers/base.py", line 115, in _get_response
    response = self.process_exception_by_middleware(e, request)
  File "/home/ubuntu/.local/lib/python3.6/site-packages/django/core/handlers/base.py", line 113, in _get_response
    response = wrapped_callback(request, *callback_args, **callback_kwargs)
  File "/home/ubuntu/.local/lib/python3.6/site-packages/django/views/decorators/csrf.py", line 54, in wrapped_view
    return view_func(*args, **kwargs)
  File "./users/views.py", line 80, in upload_tcn_rx
    user = User.objects.get(uuid=uuid)
  File "/home/ubuntu/.local/lib/python3.6/site-packages/django/db/models/manager.py", line 82, in manager_method
    return getattr(self.get_queryset(), name)(*args, **kwargs)
  File "/home/ubuntu/.local/lib/python3.6/site-packages/django/db/models/query.py", line 417, in get
    self.model._meta.object_name
users.models.User.DoesNotExist: User matching query does not exist.
2020-07-26 18:58:22,859 - ERROR: Internal Server Error: /api/upload/tcn/tx
Traceback (most recent call last):
  File "/home/ubuntu/.local/lib/python3.6/site-packages/django/core/handlers/exception.py", line 34, in inner
    response = get_response(request)
  File "/home/ubuntu/.local/lib/python3.6/site-packages/django/core/handlers/base.py", line 115, in _get_response
    response = self.process_exception_by_middleware(e, request)
  File "/home/ubuntu/.local/lib/python3.6/site-packages/django/core/handlers/base.py", line 113, in _get_response
    response = wrapped_callback(request, *callback_args, **callback_kwargs)
  File "/home/ubuntu/.local/lib/python3.6/site-packages/django/views/decorators/csrf.py", line 54, in wrapped_view
    return view_func(*args, **kwargs)
  File "./users/views.py", line 135, in upload_tcn_tx
    user = User.objects.get(uuid=uuid)
  File "/home/ubuntu/.local/lib/python3.6/site-packages/django/db/models/manager.py", line 82, in manager_method
    return getattr(self.get_queryset(), name)(*args, **kwargs)
  File "/home/ubuntu/.local/lib/python3.6/site-packages/django/db/models/query.py", line 417, in get
    self.model._meta.object_name
users.models.User.DoesNotExist: User matching query does not exist.
2020-07-26 18:58:24,329 - ERROR: Internal Server Error: /api/upload/tcn/rx
Traceback (most recent call last):
  File "/home/ubuntu/.local/lib/python3.6/site-packages/django/core/handlers/exception.py", line 34, in inner
    response = get_response(request)
  File "/home/ubuntu/.local/lib/python3.6/site-packages/django/core/handlers/base.py", line 115, in _get_response
    response = self.process_exception_by_middleware(e, request)
  File "/home/ubuntu/.local/lib/python3.6/site-packages/django/core/handlers/base.py", line 113, in _get_response
    response = wrapped_callback(request, *callback_args, **callback_kwargs)
  File "/home/ubuntu/.local/lib/python3.6/site-packages/django/views/decorators/csrf.py", line 54, in wrapped_view
    return view_func(*args, **kwargs)
  File "./users/views.py", line 80, in upload_tcn_rx
    user = User.objects.get(uuid=uuid)
  File "/home/ubuntu/.local/lib/python3.6/site-packages/django/db/models/manager.py", line 82, in manager_method
    return getattr(self.get_queryset(), name)(*args, **kwargs)
  File "/home/ubuntu/.local/lib/python3.6/site-packages/django/db/models/query.py", line 417, in get
    self.model._meta.object_name
users.models.User.DoesNotExist: User matching query does not exist.
2020-07-26 18:58:25,910 - ERROR: Internal Server Error: /api/upload/tcn/tx
Traceback (most recent call last):
  File "/home/ubuntu/.local/lib/python3.6/site-packages/django/core/handlers/exception.py", line 34, in inner
    response = get_response(request)
  File "/home/ubuntu/.local/lib/python3.6/site-packages/django/core/handlers/base.py", line 115, in _get_response
    response = self.process_exception_by_middleware(e, request)
  File "/home/ubuntu/.local/lib/python3.6/site-packages/django/core/handlers/base.py", line 113, in _get_response
    response = wrapped_callback(request, *callback_args, **callback_kwargs)
  File "/home/ubuntu/.local/lib/python3.6/site-packages/django/views/decorators/csrf.py", line 54, in wrapped_view
    return view_func(*args, **kwargs)
  File "./users/views.py", line 135, in upload_tcn_tx
    user = User.objects.get(uuid=uuid)
  File "/home/ubuntu/.local/lib/python3.6/site-packages/django/db/models/manager.py", line 82, in manager_method
    return getattr(self.get_queryset(), name)(*args, **kwargs)
  File "/home/ubuntu/.local/lib/python3.6/site-packages/django/db/models/query.py", line 417, in get
    self.model._meta.object_name
users.models.User.DoesNotExist: User matching query does not exist.
2020-07-26 18:58:27,630 - ERROR: Internal Server Error: /api/upload/tcn/rx
Traceback (most recent call last):
  File "/home/ubuntu/.local/lib/python3.6/site-packages/django/core/handlers/exception.py", line 34, in inner
    response = get_response(request)
  File "/home/ubuntu/.local/lib/python3.6/site-packages/django/core/handlers/base.py", line 115, in _get_response
    response = self.process_exception_by_middleware(e, request)
  File "/home/ubuntu/.local/lib/python3.6/site-packages/django/core/handlers/base.py", line 113, in _get_response
    response = wrapped_callback(request, *callback_args, **callback_kwargs)
  File "/home/ubuntu/.local/lib/python3.6/site-packages/django/views/decorators/csrf.py", line 54, in wrapped_view
    return view_func(*args, **kwargs)
  File "./users/views.py", line 80, in upload_tcn_rx
    user = User.objects.get(uuid=uuid)
  File "/home/ubuntu/.local/lib/python3.6/site-packages/django/db/models/manager.py", line 82, in manager_method
    return getattr(self.get_queryset(), name)(*args, **kwargs)
  File "/home/ubuntu/.local/lib/python3.6/site-packages/django/db/models/query.py", line 417, in get
    self.model._meta.object_name
users.models.User.DoesNotExist: User matching query does not exist.
2020-07-26 19:01:34,630 - ERROR: Internal Server Error: /api/upload/tcn/rx
Traceback (most recent call last):
  File "/home/ubuntu/.local/lib/python3.6/site-packages/django/core/handlers/exception.py", line 34, in inner
    response = get_response(request)
  File "/home/ubuntu/.local/lib/python3.6/site-packages/django/core/handlers/base.py", line 115, in _get_response
    response = self.process_exception_by_middleware(e, request)
  File "/home/ubuntu/.local/lib/python3.6/site-packages/django/core/handlers/base.py", line 113, in _get_response
    response = wrapped_callback(request, *callback_args, **callback_kwargs)
  File "/home/ubuntu/.local/lib/python3.6/site-packages/django/views/decorators/csrf.py", line 54, in wrapped_view
    return view_func(*args, **kwargs)
  File "./users/views.py", line 80, in upload_tcn_rx
    user = User.objects.get(uuid=uuid)
  File "/home/ubuntu/.local/lib/python3.6/site-packages/django/db/models/manager.py", line 82, in manager_method
    return getattr(self.get_queryset(), name)(*args, **kwargs)
  File "/home/ubuntu/.local/lib/python3.6/site-packages/django/db/models/query.py", line 417, in get
    self.model._meta.object_name
users.models.User.DoesNotExist: User matching query does not exist.
2020-07-26 19:01:34,631 - ERROR: Internal Server Error: /api/upload/tcn/tx
Traceback (most recent call last):
  File "/home/ubuntu/.local/lib/python3.6/site-packages/django/core/handlers/exception.py", line 34, in inner
    response = get_response(request)
  File "/home/ubuntu/.local/lib/python3.6/site-packages/django/core/handlers/base.py", line 115, in _get_response
    response = self.process_exception_by_middleware(e, request)
  File "/home/ubuntu/.local/lib/python3.6/site-packages/django/core/handlers/base.py", line 113, in _get_response
    response = wrapped_callback(request, *callback_args, **callback_kwargs)
  File "/home/ubuntu/.local/lib/python3.6/site-packages/django/views/decorators/csrf.py", line 54, in wrapped_view
    return view_func(*args, **kwargs)
  File "./users/views.py", line 135, in upload_tcn_tx
    user = User.objects.get(uuid=uuid)
  File "/home/ubuntu/.local/lib/python3.6/site-packages/django/db/models/manager.py", line 82, in manager_method
    return getattr(self.get_queryset(), name)(*args, **kwargs)
  File "/home/ubuntu/.local/lib/python3.6/site-packages/django/db/models/query.py", line 417, in get
    self.model._meta.object_name
users.models.User.DoesNotExist: User matching query does not exist.
2020-07-26 19:01:43,936 - ERROR: Internal Server Error: /api/upload/tcn/rx
Traceback (most recent call last):
  File "/home/ubuntu/.local/lib/python3.6/site-packages/django/core/handlers/exception.py", line 34, in inner
    response = get_response(request)
  File "/home/ubuntu/.local/lib/python3.6/site-packages/django/core/handlers/base.py", line 115, in _get_response
    response = self.process_exception_by_middleware(e, request)
  File "/home/ubuntu/.local/lib/python3.6/site-packages/django/core/handlers/base.py", line 113, in _get_response
    response = wrapped_callback(request, *callback_args, **callback_kwargs)
  File "/home/ubuntu/.local/lib/python3.6/site-packages/django/views/decorators/csrf.py", line 54, in wrapped_view
    return view_func(*args, **kwargs)
  File "./users/views.py", line 80, in upload_tcn_rx
    user = User.objects.get(uuid=uuid)
  File "/home/ubuntu/.local/lib/python3.6/site-packages/django/db/models/manager.py", line 82, in manager_method
    return getattr(self.get_queryset(), name)(*args, **kwargs)
  File "/home/ubuntu/.local/lib/python3.6/site-packages/django/db/models/query.py", line 417, in get
    self.model._meta.object_name
users.models.User.DoesNotExist: User matching query does not exist.
2020-07-26 19:01:43,951 - ERROR: Internal Server Error: /api/upload/tcn/tx
Traceback (most recent call last):
  File "/home/ubuntu/.local/lib/python3.6/site-packages/django/core/handlers/exception.py", line 34, in inner
    response = get_response(request)
  File "/home/ubuntu/.local/lib/python3.6/site-packages/django/core/handlers/base.py", line 115, in _get_response
    response = self.process_exception_by_middleware(e, request)
  File "/home/ubuntu/.local/lib/python3.6/site-packages/django/core/handlers/base.py", line 113, in _get_response
    response = wrapped_callback(request, *callback_args, **callback_kwargs)
  File "/home/ubuntu/.local/lib/python3.6/site-packages/django/views/decorators/csrf.py", line 54, in wrapped_view
    return view_func(*args, **kwargs)
  File "./users/views.py", line 135, in upload_tcn_tx
    user = User.objects.get(uuid=uuid)
  File "/home/ubuntu/.local/lib/python3.6/site-packages/django/db/models/manager.py", line 82, in manager_method
    return getattr(self.get_queryset(), name)(*args, **kwargs)
  File "/home/ubuntu/.local/lib/python3.6/site-packages/django/db/models/query.py", line 417, in get
    self.model._meta.object_name
users.models.User.DoesNotExist: User matching query does not exist.
2020-07-26 19:01:50,472 - ERROR: Internal Server Error: /api/upload/tcn/tx
Traceback (most recent call last):
  File "/home/ubuntu/.local/lib/python3.6/site-packages/django/core/handlers/exception.py", line 34, in inner
    response = get_response(request)
  File "/home/ubuntu/.local/lib/python3.6/site-packages/django/core/handlers/base.py", line 115, in _get_response
    response = self.process_exception_by_middleware(e, request)
  File "/home/ubuntu/.local/lib/python3.6/site-packages/django/core/handlers/base.py", line 113, in _get_response
    response = wrapped_callback(request, *callback_args, **callback_kwargs)
  File "/home/ubuntu/.local/lib/python3.6/site-packages/django/views/decorators/csrf.py", line 54, in wrapped_view
    return view_func(*args, **kwargs)
  File "./users/views.py", line 135, in upload_tcn_tx
    user = User.objects.get(uuid=uuid)
  File "/home/ubuntu/.local/lib/python3.6/site-packages/django/db/models/manager.py", line 82, in manager_method
    return getattr(self.get_queryset(), name)(*args, **kwargs)
  File "/home/ubuntu/.local/lib/python3.6/site-packages/django/db/models/query.py", line 417, in get
    self.model._meta.object_name
users.models.User.DoesNotExist: User matching query does not exist.
2020-07-26 19:01:50,475 - ERROR: Internal Server Error: /api/upload/tcn/rx
Traceback (most recent call last):
  File "/home/ubuntu/.local/lib/python3.6/site-packages/django/core/handlers/exception.py", line 34, in inner
    response = get_response(request)
  File "/home/ubuntu/.local/lib/python3.6/site-packages/django/core/handlers/base.py", line 115, in _get_response
    response = self.process_exception_by_middleware(e, request)
  File "/home/ubuntu/.local/lib/python3.6/site-packages/django/core/handlers/base.py", line 113, in _get_response
    response = wrapped_callback(request, *callback_args, **callback_kwargs)
  File "/home/ubuntu/.local/lib/python3.6/site-packages/django/views/decorators/csrf.py", line 54, in wrapped_view
    return view_func(*args, **kwargs)
  File "./users/views.py", line 80, in upload_tcn_rx
    user = User.objects.get(uuid=uuid)
  File "/home/ubuntu/.local/lib/python3.6/site-packages/django/db/models/manager.py", line 82, in manager_method
    return getattr(self.get_queryset(), name)(*args, **kwargs)
  File "/home/ubuntu/.local/lib/python3.6/site-packages/django/db/models/query.py", line 417, in get
    self.model._meta.object_name
users.models.User.DoesNotExist: User matching query does not exist.
2020-07-26 19:02:36,261 - ERROR: Internal Server Error: /api/upload/tcn/tx
Traceback (most recent call last):
  File "/home/ubuntu/.local/lib/python3.6/site-packages/django/core/handlers/exception.py", line 34, in inner
    response = get_response(request)
  File "/home/ubuntu/.local/lib/python3.6/site-packages/django/core/handlers/base.py", line 115, in _get_response
    response = self.process_exception_by_middleware(e, request)
  File "/home/ubuntu/.local/lib/python3.6/site-packages/django/core/handlers/base.py", line 113, in _get_response
    response = wrapped_callback(request, *callback_args, **callback_kwargs)
  File "/home/ubuntu/.local/lib/python3.6/site-packages/django/views/decorators/csrf.py", line 54, in wrapped_view
    return view_func(*args, **kwargs)
  File "./users/views.py", line 135, in upload_tcn_tx
    user = User.objects.get(uuid=uuid)
  File "/home/ubuntu/.local/lib/python3.6/site-packages/django/db/models/manager.py", line 82, in manager_method
    return getattr(self.get_queryset(), name)(*args, **kwargs)
  File "/home/ubuntu/.local/lib/python3.6/site-packages/django/db/models/query.py", line 417, in get
    self.model._meta.object_name
users.models.User.DoesNotExist: User matching query does not exist.
2020-07-26 19:02:36,290 - ERROR: Internal Server Error: /api/upload/tcn/rx
Traceback (most recent call last):
  File "/home/ubuntu/.local/lib/python3.6/site-packages/django/core/handlers/exception.py", line 34, in inner
    response = get_response(request)
  File "/home/ubuntu/.local/lib/python3.6/site-packages/django/core/handlers/base.py", line 115, in _get_response
    response = self.process_exception_by_middleware(e, request)
  File "/home/ubuntu/.local/lib/python3.6/site-packages/django/core/handlers/base.py", line 113, in _get_response
    response = wrapped_callback(request, *callback_args, **callback_kwargs)
  File "/home/ubuntu/.local/lib/python3.6/site-packages/django/views/decorators/csrf.py", line 54, in wrapped_view
    return view_func(*args, **kwargs)
  File "./users/views.py", line 80, in upload_tcn_rx
    user = User.objects.get(uuid=uuid)
  File "/home/ubuntu/.local/lib/python3.6/site-packages/django/db/models/manager.py", line 82, in manager_method
    return getattr(self.get_queryset(), name)(*args, **kwargs)
  File "/home/ubuntu/.local/lib/python3.6/site-packages/django/db/models/query.py", line 417, in get
    self.model._meta.object_name
users.models.User.DoesNotExist: User matching query does not exist.
2020-07-26 19:03:04,453 - ERROR: Internal Server Error: /api/upload/tcn/tx
Traceback (most recent call last):
  File "/home/ubuntu/.local/lib/python3.6/site-packages/django/core/handlers/exception.py", line 34, in inner
    response = get_response(request)
  File "/home/ubuntu/.local/lib/python3.6/site-packages/django/core/handlers/base.py", line 115, in _get_response
    response = self.process_exception_by_middleware(e, request)
  File "/home/ubuntu/.local/lib/python3.6/site-packages/django/core/handlers/base.py", line 113, in _get_response
    response = wrapped_callback(request, *callback_args, **callback_kwargs)
  File "/home/ubuntu/.local/lib/python3.6/site-packages/django/views/decorators/csrf.py", line 54, in wrapped_view
    return view_func(*args, **kwargs)
  File "./users/views.py", line 135, in upload_tcn_tx
    user = User.objects.get(uuid=uuid)
  File "/home/ubuntu/.local/lib/python3.6/site-packages/django/db/models/manager.py", line 82, in manager_method
    return getattr(self.get_queryset(), name)(*args, **kwargs)
  File "/home/ubuntu/.local/lib/python3.6/site-packages/django/db/models/query.py", line 417, in get
    self.model._meta.object_name
users.models.User.DoesNotExist: User matching query does not exist.
2020-07-26 19:03:04,482 - ERROR: Internal Server Error: /api/upload/tcn/rx
Traceback (most recent call last):
  File "/home/ubuntu/.local/lib/python3.6/site-packages/django/core/handlers/exception.py", line 34, in inner
    response = get_response(request)
  File "/home/ubuntu/.local/lib/python3.6/site-packages/django/core/handlers/base.py", line 115, in _get_response
    response = self.process_exception_by_middleware(e, request)
  File "/home/ubuntu/.local/lib/python3.6/site-packages/django/core/handlers/base.py", line 113, in _get_response
    response = wrapped_callback(request, *callback_args, **callback_kwargs)
  File "/home/ubuntu/.local/lib/python3.6/site-packages/django/views/decorators/csrf.py", line 54, in wrapped_view
    return view_func(*args, **kwargs)
  File "./users/views.py", line 80, in upload_tcn_rx
    user = User.objects.get(uuid=uuid)
  File "/home/ubuntu/.local/lib/python3.6/site-packages/django/db/models/manager.py", line 82, in manager_method
    return getattr(self.get_queryset(), name)(*args, **kwargs)
  File "/home/ubuntu/.local/lib/python3.6/site-packages/django/db/models/query.py", line 417, in get
    self.model._meta.object_name
users.models.User.DoesNotExist: User matching query does not exist.
2020-07-26 19:03:09,338 - ERROR: Internal Server Error: /api/upload/tcn/tx
Traceback (most recent call last):
  File "/home/ubuntu/.local/lib/python3.6/site-packages/django/core/handlers/exception.py", line 34, in inner
    response = get_response(request)
  File "/home/ubuntu/.local/lib/python3.6/site-packages/django/core/handlers/base.py", line 115, in _get_response
    response = self.process_exception_by_middleware(e, request)
  File "/home/ubuntu/.local/lib/python3.6/site-packages/django/core/handlers/base.py", line 113, in _get_response
    response = wrapped_callback(request, *callback_args, **callback_kwargs)
  File "/home/ubuntu/.local/lib/python3.6/site-packages/django/views/decorators/csrf.py", line 54, in wrapped_view
    return view_func(*args, **kwargs)
  File "./users/views.py", line 135, in upload_tcn_tx
    user = User.objects.get(uuid=uuid)
  File "/home/ubuntu/.local/lib/python3.6/site-packages/django/db/models/manager.py", line 82, in manager_method
    return getattr(self.get_queryset(), name)(*args, **kwargs)
  File "/home/ubuntu/.local/lib/python3.6/site-packages/django/db/models/query.py", line 417, in get
    self.model._meta.object_name
users.models.User.DoesNotExist: User matching query does not exist.
2020-07-26 19:03:09,367 - ERROR: Internal Server Error: /api/upload/tcn/rx
Traceback (most recent call last):
  File "/home/ubuntu/.local/lib/python3.6/site-packages/django/core/handlers/exception.py", line 34, in inner
    response = get_response(request)
  File "/home/ubuntu/.local/lib/python3.6/site-packages/django/core/handlers/base.py", line 115, in _get_response
    response = self.process_exception_by_middleware(e, request)
  File "/home/ubuntu/.local/lib/python3.6/site-packages/django/core/handlers/base.py", line 113, in _get_response
    response = wrapped_callback(request, *callback_args, **callback_kwargs)
  File "/home/ubuntu/.local/lib/python3.6/site-packages/django/views/decorators/csrf.py", line 54, in wrapped_view
    return view_func(*args, **kwargs)
  File "./users/views.py", line 80, in upload_tcn_rx
    user = User.objects.get(uuid=uuid)
  File "/home/ubuntu/.local/lib/python3.6/site-packages/django/db/models/manager.py", line 82, in manager_method
    return getattr(self.get_queryset(), name)(*args, **kwargs)
  File "/home/ubuntu/.local/lib/python3.6/site-packages/django/db/models/query.py", line 417, in get
    self.model._meta.object_name
users.models.User.DoesNotExist: User matching query does not exist.
2020-07-26 19:06:16,356 - ERROR: Internal Server Error: /api/upload/tcn/rx
Traceback (most recent call last):
  File "/home/ubuntu/.local/lib/python3.6/site-packages/django/core/handlers/exception.py", line 34, in inner
    response = get_response(request)
  File "/home/ubuntu/.local/lib/python3.6/site-packages/django/core/handlers/base.py", line 115, in _get_response
    response = self.process_exception_by_middleware(e, request)
  File "/home/ubuntu/.local/lib/python3.6/site-packages/django/core/handlers/base.py", line 113, in _get_response
    response = wrapped_callback(request, *callback_args, **callback_kwargs)
  File "/home/ubuntu/.local/lib/python3.6/site-packages/django/views/decorators/csrf.py", line 54, in wrapped_view
    return view_func(*args, **kwargs)
  File "./users/views.py", line 80, in upload_tcn_rx
    user = User.objects.get(uuid=uuid)
  File "/home/ubuntu/.local/lib/python3.6/site-packages/django/db/models/manager.py", line 82, in manager_method
    return getattr(self.get_queryset(), name)(*args, **kwargs)
  File "/home/ubuntu/.local/lib/python3.6/site-packages/django/db/models/query.py", line 417, in get
    self.model._meta.object_name
users.models.User.DoesNotExist: User matching query does not exist.
2020-07-26 19:06:16,357 - ERROR: Internal Server Error: /api/upload/tcn/tx
Traceback (most recent call last):
  File "/home/ubuntu/.local/lib/python3.6/site-packages/django/core/handlers/exception.py", line 34, in inner
    response = get_response(request)
  File "/home/ubuntu/.local/lib/python3.6/site-packages/django/core/handlers/base.py", line 115, in _get_response
    response = self.process_exception_by_middleware(e, request)
  File "/home/ubuntu/.local/lib/python3.6/site-packages/django/core/handlers/base.py", line 113, in _get_response
    response = wrapped_callback(request, *callback_args, **callback_kwargs)
  File "/home/ubuntu/.local/lib/python3.6/site-packages/django/views/decorators/csrf.py", line 54, in wrapped_view
    return view_func(*args, **kwargs)
  File "./users/views.py", line 135, in upload_tcn_tx
    user = User.objects.get(uuid=uuid)
  File "/home/ubuntu/.local/lib/python3.6/site-packages/django/db/models/manager.py", line 82, in manager_method
    return getattr(self.get_queryset(), name)(*args, **kwargs)
  File "/home/ubuntu/.local/lib/python3.6/site-packages/django/db/models/query.py", line 417, in get
    self.model._meta.object_name
users.models.User.DoesNotExist: User matching query does not exist.
2020-07-26 19:06:33,907 - ERROR: Internal Server Error: /api/upload/tcn/tx
Traceback (most recent call last):
  File "/home/ubuntu/.local/lib/python3.6/site-packages/django/core/handlers/exception.py", line 34, in inner
    response = get_response(request)
  File "/home/ubuntu/.local/lib/python3.6/site-packages/django/core/handlers/base.py", line 115, in _get_response
    response = self.process_exception_by_middleware(e, request)
  File "/home/ubuntu/.local/lib/python3.6/site-packages/django/core/handlers/base.py", line 113, in _get_response
    response = wrapped_callback(request, *callback_args, **callback_kwargs)
  File "/home/ubuntu/.local/lib/python3.6/site-packages/django/views/decorators/csrf.py", line 54, in wrapped_view
    return view_func(*args, **kwargs)
  File "./users/views.py", line 135, in upload_tcn_tx
    user = User.objects.get(uuid=uuid)
  File "/home/ubuntu/.local/lib/python3.6/site-packages/django/db/models/manager.py", line 82, in manager_method
    return getattr(self.get_queryset(), name)(*args, **kwargs)
  File "/home/ubuntu/.local/lib/python3.6/site-packages/django/db/models/query.py", line 417, in get
    self.model._meta.object_name
users.models.User.DoesNotExist: User matching query does not exist.
2020-07-26 19:06:33,928 - ERROR: Internal Server Error: /api/upload/tcn/rx
Traceback (most recent call last):
  File "/home/ubuntu/.local/lib/python3.6/site-packages/django/core/handlers/exception.py", line 34, in inner
    response = get_response(request)
  File "/home/ubuntu/.local/lib/python3.6/site-packages/django/core/handlers/base.py", line 115, in _get_response
    response = self.process_exception_by_middleware(e, request)
  File "/home/ubuntu/.local/lib/python3.6/site-packages/django/core/handlers/base.py", line 113, in _get_response
    response = wrapped_callback(request, *callback_args, **callback_kwargs)
  File "/home/ubuntu/.local/lib/python3.6/site-packages/django/views/decorators/csrf.py", line 54, in wrapped_view
    return view_func(*args, **kwargs)
  File "./users/views.py", line 80, in upload_tcn_rx
    user = User.objects.get(uuid=uuid)
  File "/home/ubuntu/.local/lib/python3.6/site-packages/django/db/models/manager.py", line 82, in manager_method
    return getattr(self.get_queryset(), name)(*args, **kwargs)
  File "/home/ubuntu/.local/lib/python3.6/site-packages/django/db/models/query.py", line 417, in get
    self.model._meta.object_name
users.models.User.DoesNotExist: User matching query does not exist.
2020-07-26 19:06:38,755 - ERROR: Internal Server Error: /api/upload/tcn/tx
Traceback (most recent call last):
  File "/home/ubuntu/.local/lib/python3.6/site-packages/django/core/handlers/exception.py", line 34, in inner
    response = get_response(request)
  File "/home/ubuntu/.local/lib/python3.6/site-packages/django/core/handlers/base.py", line 115, in _get_response
    response = self.process_exception_by_middleware(e, request)
  File "/home/ubuntu/.local/lib/python3.6/site-packages/django/core/handlers/base.py", line 113, in _get_response
    response = wrapped_callback(request, *callback_args, **callback_kwargs)
  File "/home/ubuntu/.local/lib/python3.6/site-packages/django/views/decorators/csrf.py", line 54, in wrapped_view
    return view_func(*args, **kwargs)
  File "./users/views.py", line 135, in upload_tcn_tx
    user = User.objects.get(uuid=uuid)
  File "/home/ubuntu/.local/lib/python3.6/site-packages/django/db/models/manager.py", line 82, in manager_method
    return getattr(self.get_queryset(), name)(*args, **kwargs)
  File "/home/ubuntu/.local/lib/python3.6/site-packages/django/db/models/query.py", line 417, in get
    self.model._meta.object_name
users.models.User.DoesNotExist: User matching query does not exist.
2020-07-26 19:06:38,783 - ERROR: Internal Server Error: /api/upload/tcn/rx
Traceback (most recent call last):
  File "/home/ubuntu/.local/lib/python3.6/site-packages/django/core/handlers/exception.py", line 34, in inner
    response = get_response(request)
  File "/home/ubuntu/.local/lib/python3.6/site-packages/django/core/handlers/base.py", line 115, in _get_response
    response = self.process_exception_by_middleware(e, request)
  File "/home/ubuntu/.local/lib/python3.6/site-packages/django/core/handlers/base.py", line 113, in _get_response
    response = wrapped_callback(request, *callback_args, **callback_kwargs)
  File "/home/ubuntu/.local/lib/python3.6/site-packages/django/views/decorators/csrf.py", line 54, in wrapped_view
    return view_func(*args, **kwargs)
  File "./users/views.py", line 80, in upload_tcn_rx
    user = User.objects.get(uuid=uuid)
  File "/home/ubuntu/.local/lib/python3.6/site-packages/django/db/models/manager.py", line 82, in manager_method
    return getattr(self.get_queryset(), name)(*args, **kwargs)
  File "/home/ubuntu/.local/lib/python3.6/site-packages/django/db/models/query.py", line 417, in get
    self.model._meta.object_name
users.models.User.DoesNotExist: User matching query does not exist.
2020-07-26 19:06:44,349 - ERROR: Internal Server Error: /api/upload/tcn/tx
Traceback (most recent call last):
  File "/home/ubuntu/.local/lib/python3.6/site-packages/django/core/handlers/exception.py", line 34, in inner
    response = get_response(request)
  File "/home/ubuntu/.local/lib/python3.6/site-packages/django/core/handlers/base.py", line 115, in _get_response
    response = self.process_exception_by_middleware(e, request)
  File "/home/ubuntu/.local/lib/python3.6/site-packages/django/core/handlers/base.py", line 113, in _get_response
    response = wrapped_callback(request, *callback_args, **callback_kwargs)
  File "/home/ubuntu/.local/lib/python3.6/site-packages/django/views/decorators/csrf.py", line 54, in wrapped_view
    return view_func(*args, **kwargs)
  File "./users/views.py", line 135, in upload_tcn_tx
    user = User.objects.get(uuid=uuid)
  File "/home/ubuntu/.local/lib/python3.6/site-packages/django/db/models/manager.py", line 82, in manager_method
    return getattr(self.get_queryset(), name)(*args, **kwargs)
  File "/home/ubuntu/.local/lib/python3.6/site-packages/django/db/models/query.py", line 417, in get
    self.model._meta.object_name
users.models.User.DoesNotExist: User matching query does not exist.
2020-07-26 19:06:44,461 - ERROR: Internal Server Error: /api/upload/tcn/rx
Traceback (most recent call last):
  File "/home/ubuntu/.local/lib/python3.6/site-packages/django/core/handlers/exception.py", line 34, in inner
    response = get_response(request)
  File "/home/ubuntu/.local/lib/python3.6/site-packages/django/core/handlers/base.py", line 115, in _get_response
    response = self.process_exception_by_middleware(e, request)
  File "/home/ubuntu/.local/lib/python3.6/site-packages/django/core/handlers/base.py", line 113, in _get_response
    response = wrapped_callback(request, *callback_args, **callback_kwargs)
  File "/home/ubuntu/.local/lib/python3.6/site-packages/django/views/decorators/csrf.py", line 54, in wrapped_view
    return view_func(*args, **kwargs)
  File "./users/views.py", line 80, in upload_tcn_rx
    user = User.objects.get(uuid=uuid)
  File "/home/ubuntu/.local/lib/python3.6/site-packages/django/db/models/manager.py", line 82, in manager_method
    return getattr(self.get_queryset(), name)(*args, **kwargs)
  File "/home/ubuntu/.local/lib/python3.6/site-packages/django/db/models/query.py", line 417, in get
    self.model._meta.object_name
users.models.User.DoesNotExist: User matching query does not exist.
2020-07-26 19:06:49,993 - ERROR: Internal Server Error: /api/upload/tcn/tx
Traceback (most recent call last):
  File "/home/ubuntu/.local/lib/python3.6/site-packages/django/core/handlers/exception.py", line 34, in inner
    response = get_response(request)
  File "/home/ubuntu/.local/lib/python3.6/site-packages/django/core/handlers/base.py", line 115, in _get_response
    response = self.process_exception_by_middleware(e, request)
  File "/home/ubuntu/.local/lib/python3.6/site-packages/django/core/handlers/base.py", line 113, in _get_response
    response = wrapped_callback(request, *callback_args, **callback_kwargs)
  File "/home/ubuntu/.local/lib/python3.6/site-packages/django/views/decorators/csrf.py", line 54, in wrapped_view
    return view_func(*args, **kwargs)
  File "./users/views.py", line 135, in upload_tcn_tx
    user = User.objects.get(uuid=uuid)
  File "/home/ubuntu/.local/lib/python3.6/site-packages/django/db/models/manager.py", line 82, in manager_method
    return getattr(self.get_queryset(), name)(*args, **kwargs)
  File "/home/ubuntu/.local/lib/python3.6/site-packages/django/db/models/query.py", line 417, in get
    self.model._meta.object_name
users.models.User.DoesNotExist: User matching query does not exist.
2020-07-26 19:06:50,036 - ERROR: Internal Server Error: /api/upload/tcn/rx
Traceback (most recent call last):
  File "/home/ubuntu/.local/lib/python3.6/site-packages/django/core/handlers/exception.py", line 34, in inner
    response = get_response(request)
  File "/home/ubuntu/.local/lib/python3.6/site-packages/django/core/handlers/base.py", line 115, in _get_response
    response = self.process_exception_by_middleware(e, request)
  File "/home/ubuntu/.local/lib/python3.6/site-packages/django/core/handlers/base.py", line 113, in _get_response
    response = wrapped_callback(request, *callback_args, **callback_kwargs)
  File "/home/ubuntu/.local/lib/python3.6/site-packages/django/views/decorators/csrf.py", line 54, in wrapped_view
    return view_func(*args, **kwargs)
  File "./users/views.py", line 80, in upload_tcn_rx
    user = User.objects.get(uuid=uuid)
  File "/home/ubuntu/.local/lib/python3.6/site-packages/django/db/models/manager.py", line 82, in manager_method
    return getattr(self.get_queryset(), name)(*args, **kwargs)
  File "/home/ubuntu/.local/lib/python3.6/site-packages/django/db/models/query.py", line 417, in get
    self.model._meta.object_name
users.models.User.DoesNotExist: User matching query does not exist.
2020-07-26 19:06:56,994 - ERROR: Internal Server Error: /api/upload/tcn/tx
Traceback (most recent call last):
  File "/home/ubuntu/.local/lib/python3.6/site-packages/django/core/handlers/exception.py", line 34, in inner
    response = get_response(request)
  File "/home/ubuntu/.local/lib/python3.6/site-packages/django/core/handlers/base.py", line 115, in _get_response
    response = self.process_exception_by_middleware(e, request)
  File "/home/ubuntu/.local/lib/python3.6/site-packages/django/core/handlers/base.py", line 113, in _get_response
    response = wrapped_callback(request, *callback_args, **callback_kwargs)
  File "/home/ubuntu/.local/lib/python3.6/site-packages/django/views/decorators/csrf.py", line 54, in wrapped_view
    return view_func(*args, **kwargs)
  File "./users/views.py", line 135, in upload_tcn_tx
    user = User.objects.get(uuid=uuid)
  File "/home/ubuntu/.local/lib/python3.6/site-packages/django/db/models/manager.py", line 82, in manager_method
    return getattr(self.get_queryset(), name)(*args, **kwargs)
  File "/home/ubuntu/.local/lib/python3.6/site-packages/django/db/models/query.py", line 417, in get
    self.model._meta.object_name
users.models.User.DoesNotExist: User matching query does not exist.
2020-07-26 19:06:57,053 - ERROR: Internal Server Error: /api/upload/tcn/rx
Traceback (most recent call last):
  File "/home/ubuntu/.local/lib/python3.6/site-packages/django/core/handlers/exception.py", line 34, in inner
    response = get_response(request)
  File "/home/ubuntu/.local/lib/python3.6/site-packages/django/core/handlers/base.py", line 115, in _get_response
    response = self.process_exception_by_middleware(e, request)
  File "/home/ubuntu/.local/lib/python3.6/site-packages/django/core/handlers/base.py", line 113, in _get_response
    response = wrapped_callback(request, *callback_args, **callback_kwargs)
  File "/home/ubuntu/.local/lib/python3.6/site-packages/django/views/decorators/csrf.py", line 54, in wrapped_view
    return view_func(*args, **kwargs)
  File "./users/views.py", line 80, in upload_tcn_rx
    user = User.objects.get(uuid=uuid)
  File "/home/ubuntu/.local/lib/python3.6/site-packages/django/db/models/manager.py", line 82, in manager_method
    return getattr(self.get_queryset(), name)(*args, **kwargs)
  File "/home/ubuntu/.local/lib/python3.6/site-packages/django/db/models/query.py", line 417, in get
    self.model._meta.object_name
users.models.User.DoesNotExist: User matching query does not exist.
2020-07-26 19:07:06,420 - ERROR: Internal Server Error: /api/upload/tcn/tx
Traceback (most recent call last):
  File "/home/ubuntu/.local/lib/python3.6/site-packages/django/core/handlers/exception.py", line 34, in inner
    response = get_response(request)
  File "/home/ubuntu/.local/lib/python3.6/site-packages/django/core/handlers/base.py", line 115, in _get_response
    response = self.process_exception_by_middleware(e, request)
  File "/home/ubuntu/.local/lib/python3.6/site-packages/django/core/handlers/base.py", line 113, in _get_response
    response = wrapped_callback(request, *callback_args, **callback_kwargs)
  File "/home/ubuntu/.local/lib/python3.6/site-packages/django/views/decorators/csrf.py", line 54, in wrapped_view
    return view_func(*args, **kwargs)
  File "./users/views.py", line 135, in upload_tcn_tx
    user = User.objects.get(uuid=uuid)
  File "/home/ubuntu/.local/lib/python3.6/site-packages/django/db/models/manager.py", line 82, in manager_method
    return getattr(self.get_queryset(), name)(*args, **kwargs)
  File "/home/ubuntu/.local/lib/python3.6/site-packages/django/db/models/query.py", line 417, in get
    self.model._meta.object_name
users.models.User.DoesNotExist: User matching query does not exist.
2020-07-26 19:07:06,470 - ERROR: Internal Server Error: /api/upload/tcn/rx
Traceback (most recent call last):
  File "/home/ubuntu/.local/lib/python3.6/site-packages/django/core/handlers/exception.py", line 34, in inner
    response = get_response(request)
  File "/home/ubuntu/.local/lib/python3.6/site-packages/django/core/handlers/base.py", line 115, in _get_response
    response = self.process_exception_by_middleware(e, request)
  File "/home/ubuntu/.local/lib/python3.6/site-packages/django/core/handlers/base.py", line 113, in _get_response
    response = wrapped_callback(request, *callback_args, **callback_kwargs)
  File "/home/ubuntu/.local/lib/python3.6/site-packages/django/views/decorators/csrf.py", line 54, in wrapped_view
    return view_func(*args, **kwargs)
  File "./users/views.py", line 80, in upload_tcn_rx
    user = User.objects.get(uuid=uuid)
  File "/home/ubuntu/.local/lib/python3.6/site-packages/django/db/models/manager.py", line 82, in manager_method
    return getattr(self.get_queryset(), name)(*args, **kwargs)
  File "/home/ubuntu/.local/lib/python3.6/site-packages/django/db/models/query.py", line 417, in get
    self.model._meta.object_name
users.models.User.DoesNotExist: User matching query does not exist.
2020-07-26 20:17:33,074 - WARNING: Not Found: /favicon.ico
2020-07-26 20:25:39,514 - WARNING: Not Found: /adminer.php
2020-07-26 20:25:39,801 - WARNING: Not Found: /favicon.ico
